[Wed Feb 19 11:57:56 2014] [error] [client 127.0.0.1] OSError: [Errno 2] No such file or directory: './static/temp/test2014-02-19 11:57:56.864374.png', referer: http://localhost:8087/extract
[Wed Feb 19 11:58:16 2014] [error] [client 127.0.0.1] Traceback (most recent call last):, referer: http://localhost:8087/extract
[Wed Feb 19 11:58:16 2014] [error] [client 127.0.0.1]   File "/Library/Python/2.7/site-packages/bottle.py", line 862, in _handle, referer: http://localhost:8087/extract
[Wed Feb 19 11:58:16 2014] [error] [client 127.0.0.1]     return route.call(**args), referer: http://localhost:8087/extract
[Wed Feb 19 11:58:16 2014] [error] [client 127.0.0.1]   File "/Library/Python/2.7/site-packages/bottle.py", line 1727, in wrapper, referer: http://localhost:8087/extract
[Wed Feb 19 11:58:16 2014] [error] [client 127.0.0.1]     rv = callback(*a, **ka), referer: http://localhost:8087/extract
[Wed Feb 19 11:58:16 2014] [error] [client 127.0.0.1]   File "/Users/mac/NLTK/jiebademo/jiebademo/wsgi.py", line 22, in serve_temp, referer: http://localhost:8087/extract
[Wed Feb 19 11:58:16 2014] [error] [client 127.0.0.1]     os.remove('./static/temp/' + filename), referer: http://localhost:8087/extract
[Wed Feb 19 11:58:16 2014] [error] [client 127.0.0.1] OSError: [Errno 2] No such file or directory: './static/temp/test2014-02-19 11:58:16.802147.png', referer: http://localhost:8087/extract
[Wed Feb 19 11:58:24 2014] [error] [client 127.0.0.1] Traceback (most recent call last):, referer: http://localhost:8087/extract
[Wed Feb 19 11:58:24 2014] [error] [client 127.0.0.1]   File "/Library/Python/2.7/site-packages/bottle.py", line 862, in _handle, referer: http://localhost:8087/extract
[Wed Feb 19 11:58:24 2014] [error] [client 127.0.0.1]     return route.call(**args), referer: http://localhost:8087/extract
[Wed Feb 19 11:58:24 2014] [error] [client 127.0.0.1]   File "/Library/Python/2.7/site-packages/bottle.py", line 1727, in wrapper, referer: http://localhost:8087/extract
[Wed Feb 19 11:58:24 2014] [error] [client 127.0.0.1]     rv = callback(*a, **ka), referer: http://localhost:8087/extract
[Wed Feb 19 11:58:24 2014] [error] [client 127.0.0.1]   File "/Users/mac/NLTK/jiebademo/jiebademo/wsgi.py", line 22, in serve_temp, referer: http://localhost:8087/extract
[Wed Feb 19 11:58:24 2014] [error] [client 127.0.0.1]     os.remove('./static/temp/' + filename), referer: http://localhost:8087/extract
[Wed Feb 19 11:58:24 2014] [error] [client 127.0.0.1] OSError: [Errno 2] No such file or directory: './static/temp/test2014-02-19 11:58:24.083288.png', referer: http://localhost:8087/extract
[Wed Feb 19 11:58:48 2014] [error] [client 127.0.0.1] Traceback (most recent call last):, referer: http://localhost:8087/extract
[Wed Feb 19 11:58:48 2014] [error] [client 127.0.0.1]   File "/Library/Python/2.7/site-packages/bottle.py", line 862, in _handle, referer: http://localhost:8087/extract
[Wed Feb 19 11:58:48 2014] [error] [client 127.0.0.1]     return route.call(**args), referer: http://localhost:8087/extract
[Wed Feb 19 11:58:48 2014] [error] [client 127.0.0.1]   File "/Library/Python/2.7/site-packages/bottle.py", line 1727, in wrapper, referer: http://localhost:8087/extract
[Wed Feb 19 11:58:48 2014] [error] [client 127.0.0.1]     rv = callback(*a, **ka), referer: http://localhost:8087/extract
[Wed Feb 19 11:58:48 2014] [error] [client 127.0.0.1]   File "/Users/mac/NLTK/jiebademo/jiebademo/wsgi.py", line 22, in serve_temp, referer: http://localhost:8087/extract
[Wed Feb 19 11:58:48 2014] [error] [client 127.0.0.1]     os.remove('./static/temp/' + filename), referer: http://localhost:8087/extract
[Wed Feb 19 11:58:48 2014] [error] [client 127.0.0.1] OSError: [Errno 2] No such file or directory: './static/temp/test2014-02-19 11:58:48.938154.png', referer: http://localhost:8087/extract
[Wed Feb 19 12:01:45 2014] [error] [client 127.0.0.1] Traceback (most recent call last):, referer: http://localhost:8087/extract
[Wed Feb 19 12:01:45 2014] [error] [client 127.0.0.1]   File "/Library/Python/2.7/site-packages/bottle.py", line 862, in _handle, referer: http://localhost:8087/extract
[Wed Feb 19 12:01:45 2014] [error] [client 127.0.0.1]     return route.call(**args), referer: http://localhost:8087/extract
[Wed Feb 19 12:01:45 2014] [error] [client 127.0.0.1]   File "/Library/Python/2.7/site-packages/bottle.py", line 1727, in wrapper, referer: http://localhost:8087/extract
[Wed Feb 19 12:01:45 2014] [error] [client 127.0.0.1]     rv = callback(*a, **ka), referer: http://localhost:8087/extract
[Wed Feb 19 12:01:45 2014] [error] [client 127.0.0.1]   File "/Users/mac/NLTK/jiebademo/jiebademo/wsgi.py", line 22, in serve_temp, referer: http://localhost:8087/extract
[Wed Feb 19 12:01:45 2014] [error] [client 127.0.0.1]     os.remove('./static/temp/' + filename), referer: http://localhost:8087/extract
[Wed Feb 19 12:01:45 2014] [error] [client 127.0.0.1] OSError: [Errno 2] No such file or directory: './static/temp/test2014-02-19 12:01:45.616163.png', referer: http://localhost:8087/extract
[Wed Feb 19 12:06:04 2014] [error] [client 127.0.0.1] Traceback (most recent call last):, referer: http://localhost:8087/extract
[Wed Feb 19 12:06:04 2014] [error] [client 127.0.0.1]   File "/Library/Python/2.7/site-packages/bottle.py", line 862, in _handle, referer: http://localhost:8087/extract
[Wed Feb 19 12:06:04 2014] [error] [client 127.0.0.1]     return route.call(**args), referer: http://localhost:8087/extract
[Wed Feb 19 12:06:04 2014] [error] [client 127.0.0.1]   File "/Library/Python/2.7/site-packages/bottle.py", line 1727, in wrapper, referer: http://localhost:8087/extract
[Wed Feb 19 12:06:04 2014] [error] [client 127.0.0.1]     rv = callback(*a, **ka), referer: http://localhost:8087/extract
[Wed Feb 19 12:06:04 2014] [error] [client 127.0.0.1]   File "/Users/mac/NLTK/jiebademo/jiebademo/wsgi.py", line 87, in extractFile_action, referer: http://localhost:8087/extract
[Wed Feb 19 12:06:04 2014] [error] [client 127.0.0.1]     fd = FreqDist(tags), referer: http://localhost:8087/extract
[Wed Feb 19 12:06:04 2014] [error] [client 127.0.0.1] NameError: global name 'FreqDist' is not defined, referer: http://localhost:8087/extract
[Wed Feb 19 12:08:35 2014] [error] [client 127.0.0.1] Traceback (most recent call last):
[Wed Feb 19 12:08:35 2014] [error] [client 127.0.0.1]   File "/Library/Python/2.7/site-packages/bottle.py", line 862, in _handle
[Wed Feb 19 12:08:35 2014] [error] [client 127.0.0.1]     return route.call(**args)
[Wed Feb 19 12:08:35 2014] [error] [client 127.0.0.1]   File "/Library/Python/2.7/site-packages/bottle.py", line 1727, in wrapper
[Wed Feb 19 12:08:35 2014] [error] [client 127.0.0.1]     rv = callback(*a, **ka)
[Wed Feb 19 12:08:35 2014] [error] [client 127.0.0.1]   File "/Users/mac/NLTK/jiebademo/jiebademo/wsgi.py", line 23, in serve_temp
[Wed Feb 19 12:08:35 2014] [error] [client 127.0.0.1]     os.remove('./static/temp/' + filename)
[Wed Feb 19 12:08:35 2014] [error] [client 127.0.0.1] OSError: [Errno 2] No such file or directory: './static/temp/test2014-02-19 12:07:22.793380.png'
[Wed Feb 19 12:08:39 2014] [error] [client 127.0.0.1] Traceback (most recent call last):
[Wed Feb 19 12:08:39 2014] [error] [client 127.0.0.1]   File "/Library/Python/2.7/site-packages/bottle.py", line 862, in _handle
[Wed Feb 19 12:08:39 2014] [error] [client 127.0.0.1]     return route.call(**args)
[Wed Feb 19 12:08:39 2014] [error] [client 127.0.0.1]   File "/Library/Python/2.7/site-packages/bottle.py", line 1727, in wrapper
[Wed Feb 19 12:08:39 2014] [error] [client 127.0.0.1]     rv = callback(*a, **ka)
[Wed Feb 19 12:08:39 2014] [error] [client 127.0.0.1]   File "/Users/mac/NLTK/jiebademo/jiebademo/wsgi.py", line 23, in serve_temp
[Wed Feb 19 12:08:39 2014] [error] [client 127.0.0.1]     os.remove('./static/temp/' + filename)
[Wed Feb 19 12:08:39 2014] [error] [client 127.0.0.1] OSError: [Errno 2] No such file or directory: './static/temp/test2014-02-19 12:07:22.793380.png'
[Wed Feb 19 12:51:35 2014] [error] [client 127.0.0.1] mod_wsgi (pid=2414): Exception occurred processing WSGI script '/Users/mac/NLTK/jiebademo/jiebademo/adapter.wsgi'., referer: http://localhost:8087/mozi.txt
[Wed Feb 19 12:51:35 2014] [error] [client 127.0.0.1] IOError: failed to write data, referer: http://localhost:8087/mozi.txt
[Wed Feb 19 12:57:53 2014] [error] [client 127.0.0.1] Traceback (most recent call last):, referer: http://localhost:8087/extract
[Wed Feb 19 12:57:53 2014] [error] [client 127.0.0.1]   File "/Library/Python/2.7/site-packages/bottle.py", line 862, in _handle, referer: http://localhost:8087/extract
[Wed Feb 19 12:57:53 2014] [error] [client 127.0.0.1]     return route.call(**args), referer: http://localhost:8087/extract
[Wed Feb 19 12:57:53 2014] [error] [client 127.0.0.1]   File "/Library/Python/2.7/site-packages/bottle.py", line 1727, in wrapper, referer: http://localhost:8087/extract
[Wed Feb 19 12:57:53 2014] [error] [client 127.0.0.1]     rv = callback(*a, **ka), referer: http://localhost:8087/extract
[Wed Feb 19 12:57:53 2014] [error] [client 127.0.0.1]   File "/Users/mac/NLTK/jiebademo/jiebademo/wsgi.py", line 176, in extractSubmit_action, referer: http://localhost:8087/extract
[Wed Feb 19 12:57:53 2014] [error] [client 127.0.0.1]     plt.axis(range(len(fd)), fd.values(), align='center'), referer: http://localhost:8087/extract
[Wed Feb 19 12:57:53 2014] [error] [client 127.0.0.1]   File "/System/Library/Frameworks/Python.framework/Versions/2.7/Extras/lib/python/matplotlib/pyplot.py", line 1157, in axis, referer: http://localhost:8087/extract
[Wed Feb 19 12:57:53 2014] [error] [client 127.0.0.1]     v = ax.axis(*v, **kwargs), referer: http://localhost:8087/extract
[Wed Feb 19 12:57:53 2014] [error] [client 127.0.0.1]   File "/System/Library/Frameworks/Python.framework/Versions/2.7/Extras/lib/python/matplotlib/axes.py", line 1320, in axis, referer: http://localhost:8087/extract
[Wed Feb 19 12:57:53 2014] [error] [client 127.0.0.1]     raise ValueError('v must contain [xmin xmax ymin ymax]'), referer: http://localhost:8087/extract
[Wed Feb 19 12:57:53 2014] [error] [client 127.0.0.1] ValueError: v must contain [xmin xmax ymin ymax], referer: http://localhost:8087/extract
[Wed Feb 19 13:03:33 2014] [error] [client 127.0.0.1] Traceback (most recent call last):, referer: http://localhost:8087/extract
[Wed Feb 19 13:03:33 2014] [error] [client 127.0.0.1]   File "/Library/Python/2.7/site-packages/bottle.py", line 862, in _handle, referer: http://localhost:8087/extract
[Wed Feb 19 13:03:33 2014] [error] [client 127.0.0.1]     return route.call(**args), referer: http://localhost:8087/extract
[Wed Feb 19 13:03:33 2014] [error] [client 127.0.0.1]   File "/Library/Python/2.7/site-packages/bottle.py", line 1727, in wrapper, referer: http://localhost:8087/extract
[Wed Feb 19 13:03:33 2014] [error] [client 127.0.0.1]     rv = callback(*a, **ka), referer: http://localhost:8087/extract
[Wed Feb 19 13:03:33 2014] [error] [client 127.0.0.1]   File "/Users/mac/NLTK/jiebademo/jiebademo/wsgi.py", line 176, in extractSubmit_action, referer: http://localhost:8087/extract
[Wed Feb 19 13:03:33 2014] [error] [client 127.0.0.1]     plt.plot(fd.keys(), fd.values(), 'ro'), referer: http://localhost:8087/extract
[Wed Feb 19 13:03:33 2014] [error] [client 127.0.0.1]   File "/System/Library/Frameworks/Python.framework/Versions/2.7/Extras/lib/python/matplotlib/pyplot.py", line 2467, in plot, referer: http://localhost:8087/extract
[Wed Feb 19 13:03:33 2014] [error] [client 127.0.0.1]     ret = ax.plot(*args, **kwargs), referer: http://localhost:8087/extract
[Wed Feb 19 13:03:33 2014] [error] [client 127.0.0.1]   File "/System/Library/Frameworks/Python.framework/Versions/2.7/Extras/lib/python/matplotlib/axes.py", line 3894, in plot, referer: http://localhost:8087/extract
[Wed Feb 19 13:03:33 2014] [error] [client 127.0.0.1]     self.add_line(line), referer: http://localhost:8087/extract
[Wed Feb 19 13:03:33 2014] [error] [client 127.0.0.1]   File "/System/Library/Frameworks/Python.framework/Versions/2.7/Extras/lib/python/matplotlib/axes.py", line 1461, in add_line, referer: http://localhost:8087/extract
[Wed Feb 19 13:03:33 2014] [error] [client 127.0.0.1]     self._update_line_limits(line), referer: http://localhost:8087/extract
[Wed Feb 19 13:03:33 2014] [error] [client 127.0.0.1]   File "/System/Library/Frameworks/Python.framework/Versions/2.7/Extras/lib/python/matplotlib/axes.py", line 1469, in _update_line_limits, referer: http://localhost:8087/extract
[Wed Feb 19 13:03:33 2014] [error] [client 127.0.0.1]     p = line.get_path(), referer: http://localhost:8087/extract
[Wed Feb 19 13:03:33 2014] [error] [client 127.0.0.1]   File "/System/Library/Frameworks/Python.framework/Versions/2.7/Extras/lib/python/matplotlib/lines.py", line 653, in get_path, referer: http://localhost:8087/extract
[Wed Feb 19 13:03:33 2014] [error] [client 127.0.0.1]     self.recache(), referer: http://localhost:8087/extract
[Wed Feb 19 13:03:33 2014] [error] [client 127.0.0.1]   File "/System/Library/Frameworks/Python.framework/Versions/2.7/Extras/lib/python/matplotlib/lines.py", line 392, in recache, referer: http://localhost:8087/extract
[Wed Feb 19 13:03:33 2014] [error] [client 127.0.0.1]     x = np.asarray(xconv, np.float_), referer: http://localhost:8087/extract
[Wed Feb 19 13:03:33 2014] [error] [client 127.0.0.1]   File "/Library/Python/2.7/site-packages/numpy-1.8.0-py2.7-macosx-10.9-intel.egg/numpy/core/numeric.py", line 460, in asarray, referer: http://localhost:8087/extract
[Wed Feb 19 13:03:33 2014] [error] [client 127.0.0.1]     return array(a, dtype, copy=False, order=order), referer: http://localhost:8087/extract
[Wed Feb 19 13:03:33 2014] [error] [client 127.0.0.1] UnicodeEncodeError: 'decimal' codec can't encode characters in position 0-1: invalid decimal Unicode string, referer: http://localhost:8087/extract
[Wed Feb 19 13:05:04 2014] [error] [client 127.0.0.1] Traceback (most recent call last):, referer: http://localhost:8087/extract
[Wed Feb 19 13:05:04 2014] [error] [client 127.0.0.1]   File "/Library/Python/2.7/site-packages/bottle.py", line 862, in _handle, referer: http://localhost:8087/extract
[Wed Feb 19 13:05:04 2014] [error] [client 127.0.0.1]     return route.call(**args), referer: http://localhost:8087/extract
[Wed Feb 19 13:05:04 2014] [error] [client 127.0.0.1]   File "/Library/Python/2.7/site-packages/bottle.py", line 1727, in wrapper, referer: http://localhost:8087/extract
[Wed Feb 19 13:05:04 2014] [error] [client 127.0.0.1]     rv = callback(*a, **ka), referer: http://localhost:8087/extract
[Wed Feb 19 13:05:04 2014] [error] [client 127.0.0.1]   File "/Users/mac/NLTK/jiebademo/jiebademo/wsgi.py", line 176, in extractSubmit_action, referer: http://localhost:8087/extract
[Wed Feb 19 13:05:04 2014] [error] [client 127.0.0.1]     plt.yticks(range(len(fd)), fd.values(), align='center'), referer: http://localhost:8087/extract
[Wed Feb 19 13:05:04 2014] [error] [client 127.0.0.1]   File "/System/Library/Frameworks/Python.framework/Versions/2.7/Extras/lib/python/matplotlib/pyplot.py", line 1362, in yticks, referer: http://localhost:8087/extract
[Wed Feb 19 13:05:04 2014] [error] [client 127.0.0.1]     labels = ax.set_yticklabels(args[1], **kwargs), referer: http://localhost:8087/extract
[Wed Feb 19 13:05:04 2014] [error] [client 127.0.0.1]   File "/System/Library/Frameworks/Python.framework/Versions/2.7/Extras/lib/python/matplotlib/axes.py", line 2770, in set_yticklabels, referer: http://localhost:8087/extract
[Wed Feb 19 13:05:04 2014] [error] [client 127.0.0.1]     minor=minor, **kwargs), referer: http://localhost:8087/extract
[Wed Feb 19 13:05:04 2014] [error] [client 127.0.0.1]   File "/System/Library/Frameworks/Python.framework/Versions/2.7/Extras/lib/python/matplotlib/axis.py", line 1457, in set_ticklabels, referer: http://localhost:8087/extract
[Wed Feb 19 13:05:04 2014] [error] [client 127.0.0.1]     tick.label1.update(kwargs), referer: http://localhost:8087/extract
[Wed Feb 19 13:05:04 2014] [error] [client 127.0.0.1]   File "/System/Library/Frameworks/Python.framework/Versions/2.7/Extras/lib/python/matplotlib/artist.py", line 659, in update, referer: http://localhost:8087/extract
[Wed Feb 19 13:05:04 2014] [error] [client 127.0.0.1]     raise AttributeError('Unknown property %s'%k), referer: http://localhost:8087/extract
[Wed Feb 19 13:05:04 2014] [error] [client 127.0.0.1] AttributeError: Unknown property align, referer: http://localhost:8087/extract
[Wed Feb 19 13:17:19 2014] [error] [client 127.0.0.1] Traceback (most recent call last):, referer: http://localhost:8087/extract
[Wed Feb 19 13:17:19 2014] [error] [client 127.0.0.1]   File "/Library/Python/2.7/site-packages/bottle.py", line 862, in _handle, referer: http://localhost:8087/extract
[Wed Feb 19 13:17:19 2014] [error] [client 127.0.0.1]     return route.call(**args), referer: http://localhost:8087/extract
[Wed Feb 19 13:17:19 2014] [error] [client 127.0.0.1]   File "/Library/Python/2.7/site-packages/bottle.py", line 1727, in wrapper, referer: http://localhost:8087/extract
[Wed Feb 19 13:17:19 2014] [error] [client 127.0.0.1]     rv = callback(*a, **ka), referer: http://localhost:8087/extract
[Wed Feb 19 13:17:19 2014] [error] [client 127.0.0.1]   File "/Users/mac/NLTK/jiebademo/jiebademo/wsgi.py", line 178, in extractSubmit_action, referer: http://localhost:8087/extract
[Wed Feb 19 13:17:19 2014] [error] [client 127.0.0.1]     plt.plot(fd.keys(), fd.values()), referer: http://localhost:8087/extract
[Wed Feb 19 13:17:19 2014] [error] [client 127.0.0.1]   File "/System/Library/Frameworks/Python.framework/Versions/2.7/Extras/lib/python/matplotlib/pyplot.py", line 2467, in plot, referer: http://localhost:8087/extract
[Wed Feb 19 13:17:19 2014] [error] [client 127.0.0.1]     ret = ax.plot(*args, **kwargs), referer: http://localhost:8087/extract
[Wed Feb 19 13:17:19 2014] [error] [client 127.0.0.1]   File "/System/Library/Frameworks/Python.framework/Versions/2.7/Extras/lib/python/matplotlib/axes.py", line 3894, in plot, referer: http://localhost:8087/extract
[Wed Feb 19 13:17:19 2014] [error] [client 127.0.0.1]     self.add_line(line), referer: http://localhost:8087/extract
[Wed Feb 19 13:17:19 2014] [error] [client 127.0.0.1]   File "/System/Library/Frameworks/Python.framework/Versions/2.7/Extras/lib/python/matplotlib/axes.py", line 1461, in add_line, referer: http://localhost:8087/extract
[Wed Feb 19 13:17:19 2014] [error] [client 127.0.0.1]     self._update_line_limits(line), referer: http://localhost:8087/extract
[Wed Feb 19 13:17:19 2014] [error] [client 127.0.0.1]   File "/System/Library/Frameworks/Python.framework/Versions/2.7/Extras/lib/python/matplotlib/axes.py", line 1469, in _update_line_limits, referer: http://localhost:8087/extract
[Wed Feb 19 13:17:19 2014] [error] [client 127.0.0.1]     p = line.get_path(), referer: http://localhost:8087/extract
[Wed Feb 19 13:17:19 2014] [error] [client 127.0.0.1]   File "/System/Library/Frameworks/Python.framework/Versions/2.7/Extras/lib/python/matplotlib/lines.py", line 653, in get_path, referer: http://localhost:8087/extract
[Wed Feb 19 13:17:19 2014] [error] [client 127.0.0.1]     self.recache(), referer: http://localhost:8087/extract
[Wed Feb 19 13:17:19 2014] [error] [client 127.0.0.1]   File "/System/Library/Frameworks/Python.framework/Versions/2.7/Extras/lib/python/matplotlib/lines.py", line 392, in recache, referer: http://localhost:8087/extract
[Wed Feb 19 13:17:19 2014] [error] [client 127.0.0.1]     x = np.asarray(xconv, np.float_), referer: http://localhost:8087/extract
[Wed Feb 19 13:17:19 2014] [error] [client 127.0.0.1]   File "/Library/Python/2.7/site-packages/numpy-1.8.0-py2.7-macosx-10.9-intel.egg/numpy/core/numeric.py", line 460, in asarray, referer: http://localhost:8087/extract
[Wed Feb 19 13:17:19 2014] [error] [client 127.0.0.1]     return array(a, dtype, copy=False, order=order), referer: http://localhost:8087/extract
[Wed Feb 19 13:17:19 2014] [error] [client 127.0.0.1] UnicodeEncodeError: 'decimal' codec can't encode characters in position 0-1: invalid decimal Unicode string, referer: http://localhost:8087/extract
[Wed Feb 19 13:20:45 2014] [error] [client 127.0.0.1] Traceback (most recent call last):, referer: http://localhost:8087/extract
[Wed Feb 19 13:20:45 2014] [error] [client 127.0.0.1]   File "/Library/Python/2.7/site-packages/bottle.py", line 862, in _handle, referer: http://localhost:8087/extract
[Wed Feb 19 13:20:45 2014] [error] [client 127.0.0.1]     return route.call(**args), referer: http://localhost:8087/extract
[Wed Feb 19 13:20:45 2014] [error] [client 127.0.0.1]   File "/Library/Python/2.7/site-packages/bottle.py", line 1727, in wrapper, referer: http://localhost:8087/extract
[Wed Feb 19 13:20:45 2014] [error] [client 127.0.0.1]     rv = callback(*a, **ka), referer: http://localhost:8087/extract
[Wed Feb 19 13:20:45 2014] [error] [client 127.0.0.1]   File "/Users/mac/NLTK/jiebademo/jiebademo/wsgi.py", line 165, in extractSubmit_action, referer: http://localhost:8087/extract
[Wed Feb 19 13:20:45 2014] [error] [client 127.0.0.1]     fd[keyword] = count, referer: http://localhost:8087/extract
[Wed Feb 19 13:20:45 2014] [error] [client 127.0.0.1] TypeError: list indices must be integers, not unicode, referer: http://localhost:8087/extract
[Wed Feb 19 13:44:57 2014] [error] [client 127.0.0.1] Traceback (most recent call last):, referer: http://localhost:8087/extract
[Wed Feb 19 13:44:57 2014] [error] [client 127.0.0.1]   File "/Library/Python/2.7/site-packages/bottle.py", line 862, in _handle, referer: http://localhost:8087/extract
[Wed Feb 19 13:44:57 2014] [error] [client 127.0.0.1]     return route.call(**args), referer: http://localhost:8087/extract
[Wed Feb 19 13:44:57 2014] [error] [client 127.0.0.1]   File "/Library/Python/2.7/site-packages/bottle.py", line 1727, in wrapper, referer: http://localhost:8087/extract
[Wed Feb 19 13:44:57 2014] [error] [client 127.0.0.1]     rv = callback(*a, **ka), referer: http://localhost:8087/extract
[Wed Feb 19 13:44:57 2014] [error] [client 127.0.0.1]   File "/Users/mac/NLTK/jiebademo/jiebademo/wsgi.py", line 165, in extractSubmit_action, referer: http://localhost:8087/extract
[Wed Feb 19 13:44:57 2014] [error] [client 127.0.0.1]     fd[keyword] = count, referer: http://localhost:8087/extract
[Wed Feb 19 13:44:57 2014] [error] [client 127.0.0.1] TypeError: list indices must be integers, not unicode, referer: http://localhost:8087/extract
[Wed Feb 19 13:47:49 2014] [error] [client 127.0.0.1] Traceback (most recent call last):, referer: http://localhost:8087/extract
[Wed Feb 19 13:47:49 2014] [error] [client 127.0.0.1]   File "/Library/Python/2.7/site-packages/bottle.py", line 862, in _handle, referer: http://localhost:8087/extract
[Wed Feb 19 13:47:49 2014] [error] [client 127.0.0.1]     return route.call(**args), referer: http://localhost:8087/extract
[Wed Feb 19 13:47:49 2014] [error] [client 127.0.0.1]   File "/Library/Python/2.7/site-packages/bottle.py", line 1727, in wrapper, referer: http://localhost:8087/extract
[Wed Feb 19 13:47:49 2014] [error] [client 127.0.0.1]     rv = callback(*a, **ka), referer: http://localhost:8087/extract
[Wed Feb 19 13:47:49 2014] [error] [client 127.0.0.1]   File "/Users/mac/NLTK/jiebademo/jiebademo/wsgi.py", line 165, in extractSubmit_action, referer: http://localhost:8087/extract
[Wed Feb 19 13:47:49 2014] [error] [client 127.0.0.1]     fd[keyword] = count, referer: http://localhost:8087/extract
[Wed Feb 19 13:47:49 2014] [error] [client 127.0.0.1] TypeError: list indices must be integers, not unicode, referer: http://localhost:8087/extract
[Wed Feb 19 16:04:18 2014] [error] [client 127.0.0.1] Traceback (most recent call last):, referer: http://localhost:8087/extract
[Wed Feb 19 16:04:18 2014] [error] [client 127.0.0.1]   File "/Library/Python/2.7/site-packages/bottle.py", line 862, in _handle, referer: http://localhost:8087/extract
[Wed Feb 19 16:04:18 2014] [error] [client 127.0.0.1]     return route.call(**args), referer: http://localhost:8087/extract
[Wed Feb 19 16:04:18 2014] [error] [client 127.0.0.1]   File "/Library/Python/2.7/site-packages/bottle.py", line 1727, in wrapper, referer: http://localhost:8087/extract
[Wed Feb 19 16:04:18 2014] [error] [client 127.0.0.1]     rv = callback(*a, **ka), referer: http://localhost:8087/extract
[Wed Feb 19 16:04:18 2014] [error] [client 127.0.0.1]   File "/Users/mac/NLTK/jiebademo/jiebademo/wsgi.py", line 165, in extractSubmit_action, referer: http://localhost:8087/extract
[Wed Feb 19 16:04:18 2014] [error] [client 127.0.0.1]     fd[keyword] = count, referer: http://localhost:8087/extract
[Wed Feb 19 16:04:18 2014] [error] [client 127.0.0.1] TypeError: list indices must be integers, not unicode, referer: http://localhost:8087/extract
[Wed Feb 19 17:19:37 2014] [error] [client 127.0.0.1] Traceback (most recent call last):, referer: http://localhost:8087/extract
[Wed Feb 19 17:19:37 2014] [error] [client 127.0.0.1]   File "/Library/Python/2.7/site-packages/bottle.py", line 862, in _handle, referer: http://localhost:8087/extract
[Wed Feb 19 17:19:37 2014] [error] [client 127.0.0.1]     return route.call(**args), referer: http://localhost:8087/extract
[Wed Feb 19 17:19:37 2014] [error] [client 127.0.0.1]   File "/Library/Python/2.7/site-packages/bottle.py", line 1727, in wrapper, referer: http://localhost:8087/extract
[Wed Feb 19 17:19:37 2014] [error] [client 127.0.0.1]     rv = callback(*a, **ka), referer: http://localhost:8087/extract
[Wed Feb 19 17:19:37 2014] [error] [client 127.0.0.1]   File "/Users/mac/NLTK/jiebademo/jiebademo/wsgi.py", line 165, in extractSubmit_action, referer: http://localhost:8087/extract
[Wed Feb 19 17:19:37 2014] [error] [client 127.0.0.1]     fd[keyword] = count, referer: http://localhost:8087/extract
[Wed Feb 19 17:19:37 2014] [error] [client 127.0.0.1] TypeError: list indices must be integers, not unicode, referer: http://localhost:8087/extract
[Wed Feb 19 17:39:24 2014] [error] [client 127.0.0.1] mod_wsgi (pid=3218): Target WSGI script '/Users/mac/NLTK/jiebademo/jiebademo/adapter.wsgi' cannot be loaded as Python module.
[Wed Feb 19 17:39:24 2014] [error] [client 127.0.0.1] mod_wsgi (pid=3218): Exception occurred processing WSGI script '/Users/mac/NLTK/jiebademo/jiebademo/adapter.wsgi'.
[Wed Feb 19 17:39:24 2014] [error] [client 127.0.0.1] Traceback (most recent call last):
[Wed Feb 19 17:39:24 2014] [error] [client 127.0.0.1]   File "/Users/mac/NLTK/jiebademo/jiebademo/adapter.wsgi", line 8, in <module>
[Wed Feb 19 17:39:24 2014] [error] [client 127.0.0.1]     import wsgi # This loads your application
[Wed Feb 19 17:39:24 2014] [error] [client 127.0.0.1]   File "/Users/mac/NLTK/jiebademo/jiebademo/wsgi.py", line 188
[Wed Feb 19 17:39:24 2014] [error] [client 127.0.0.1]     return template("extract_form",content=text,tags=tagsString,topk=topk,keyImgUrl=imgUrl, texts=sqlitedb.getTexts())
[Wed Feb 19 17:39:24 2014] [error] [client 127.0.0.1]          ^
[Wed Feb 19 17:39:24 2014] [error] [client 127.0.0.1] IndentationError: expected an indented block
[Wed Feb 19 17:39:26 2014] [error] [client 127.0.0.1] mod_wsgi (pid=3218): Target WSGI script '/Users/mac/NLTK/jiebademo/jiebademo/adapter.wsgi' cannot be loaded as Python module.
[Wed Feb 19 17:39:26 2014] [error] [client 127.0.0.1] mod_wsgi (pid=3218): Exception occurred processing WSGI script '/Users/mac/NLTK/jiebademo/jiebademo/adapter.wsgi'.
[Wed Feb 19 17:39:26 2014] [error] [client 127.0.0.1] Traceback (most recent call last):
[Wed Feb 19 17:39:26 2014] [error] [client 127.0.0.1]   File "/Users/mac/NLTK/jiebademo/jiebademo/adapter.wsgi", line 8, in <module>
[Wed Feb 19 17:39:26 2014] [error] [client 127.0.0.1]     import wsgi # This loads your application
[Wed Feb 19 17:39:26 2014] [error] [client 127.0.0.1]   File "/Users/mac/NLTK/jiebademo/jiebademo/wsgi.py", line 188
[Wed Feb 19 17:39:26 2014] [error] [client 127.0.0.1]     return template("extract_form",content=text,tags=tagsString,topk=topk,keyImgUrl=imgUrl, texts=sqlitedb.getTexts())
[Wed Feb 19 17:39:26 2014] [error] [client 127.0.0.1]          ^
[Wed Feb 19 17:39:26 2014] [error] [client 127.0.0.1] IndentationError: expected an indented block
[Wed Feb 19 17:39:31 2014] [error] [client 127.0.0.1] mod_wsgi (pid=3218): Target WSGI script '/Users/mac/NLTK/jiebademo/jiebademo/adapter.wsgi' cannot be loaded as Python module.
[Wed Feb 19 17:39:31 2014] [error] [client 127.0.0.1] mod_wsgi (pid=3218): Exception occurred processing WSGI script '/Users/mac/NLTK/jiebademo/jiebademo/adapter.wsgi'.
[Wed Feb 19 17:39:31 2014] [error] [client 127.0.0.1] Traceback (most recent call last):
[Wed Feb 19 17:39:31 2014] [error] [client 127.0.0.1]   File "/Users/mac/NLTK/jiebademo/jiebademo/adapter.wsgi", line 8, in <module>
[Wed Feb 19 17:39:31 2014] [error] [client 127.0.0.1]     import wsgi # This loads your application
[Wed Feb 19 17:39:31 2014] [error] [client 127.0.0.1]   File "/Users/mac/NLTK/jiebademo/jiebademo/wsgi.py", line 188
[Wed Feb 19 17:39:31 2014] [error] [client 127.0.0.1]     return template("extract_form",content=text,tags=tagsString,topk=topk,keyImgUrl=imgUrl, texts=sqlitedb.getTexts())
[Wed Feb 19 17:39:31 2014] [error] [client 127.0.0.1]          ^
[Wed Feb 19 17:39:31 2014] [error] [client 127.0.0.1] IndentationError: expected an indented block
[Wed Feb 19 17:39:52 2014] [error] [client 127.0.0.1] Traceback (most recent call last):, referer: http://localhost:8087/extract
[Wed Feb 19 17:39:52 2014] [error] [client 127.0.0.1]   File "/Library/Python/2.7/site-packages/bottle.py", line 862, in _handle, referer: http://localhost:8087/extract
[Wed Feb 19 17:39:52 2014] [error] [client 127.0.0.1]     return route.call(**args), referer: http://localhost:8087/extract
[Wed Feb 19 17:39:52 2014] [error] [client 127.0.0.1]   File "/Library/Python/2.7/site-packages/bottle.py", line 1727, in wrapper, referer: http://localhost:8087/extract
[Wed Feb 19 17:39:52 2014] [error] [client 127.0.0.1]     rv = callback(*a, **ka), referer: http://localhost:8087/extract
[Wed Feb 19 17:39:52 2014] [error] [client 127.0.0.1]   File "/Users/mac/NLTK/jiebademo/jiebademo/wsgi.py", line 170, in extractSubmit_action, referer: http://localhost:8087/extract
[Wed Feb 19 17:39:52 2014] [error] [client 127.0.0.1]     for key,val in fd.iteritems():, referer: http://localhost:8087/extract
[Wed Feb 19 17:39:52 2014] [error] [client 127.0.0.1] AttributeError: 'list' object has no attribute 'iteritems', referer: http://localhost:8087/extract
[Wed Feb 19 17:40:34 2014] [error] [client 127.0.0.1] Traceback (most recent call last):, referer: http://localhost:8087/extract
[Wed Feb 19 17:40:34 2014] [error] [client 127.0.0.1]   File "/Library/Python/2.7/site-packages/bottle.py", line 862, in _handle, referer: http://localhost:8087/extract
[Wed Feb 19 17:40:34 2014] [error] [client 127.0.0.1]     return route.call(**args), referer: http://localhost:8087/extract
[Wed Feb 19 17:40:34 2014] [error] [client 127.0.0.1]   File "/Library/Python/2.7/site-packages/bottle.py", line 1727, in wrapper, referer: http://localhost:8087/extract
[Wed Feb 19 17:40:34 2014] [error] [client 127.0.0.1]     rv = callback(*a, **ka), referer: http://localhost:8087/extract
[Wed Feb 19 17:40:34 2014] [error] [client 127.0.0.1]   File "/Users/mac/NLTK/jiebademo/jiebademo/wsgi.py", line 170, in extractSubmit_action, referer: http://localhost:8087/extract
[Wed Feb 19 17:40:34 2014] [error] [client 127.0.0.1]     for key,val in fd.iteritems():, referer: http://localhost:8087/extract
[Wed Feb 19 17:40:34 2014] [error] [client 127.0.0.1] AttributeError: 'list' object has no attribute 'iteritems', referer: http://localhost:8087/extract
[Wed Feb 19 18:01:19 2014] [error] [client 127.0.0.1] Traceback (most recent call last):, referer: http://localhost:8087/extract
[Wed Feb 19 18:01:19 2014] [error] [client 127.0.0.1]   File "/Library/Python/2.7/site-packages/bottle.py", line 862, in _handle, referer: http://localhost:8087/extract
[Wed Feb 19 18:01:19 2014] [error] [client 127.0.0.1]     return route.call(**args), referer: http://localhost:8087/extract
[Wed Feb 19 18:01:19 2014] [error] [client 127.0.0.1]   File "/Library/Python/2.7/site-packages/bottle.py", line 1727, in wrapper, referer: http://localhost:8087/extract
[Wed Feb 19 18:01:19 2014] [error] [client 127.0.0.1]     rv = callback(*a, **ka), referer: http://localhost:8087/extract
[Wed Feb 19 18:01:19 2014] [error] [client 127.0.0.1]   File "/Users/mac/NLTK/jiebademo/jiebademo/wsgi.py", line 24, in serve_temp, referer: http://localhost:8087/extract
[Wed Feb 19 18:01:19 2014] [error] [client 127.0.0.1]     os.remove('./static/temp/' + filename), referer: http://localhost:8087/extract
[Wed Feb 19 18:01:19 2014] [error] [client 127.0.0.1] OSError: [Errno 2] No such file or directory: './static/temp/test2014-02-19 17:53:52.827458.png', referer: http://localhost:8087/extract
[Thu Feb 20 09:59:11 2014] [error] [client 127.0.0.1] Traceback (most recent call last):, referer: http://www.youtube.com/
[Thu Feb 20 09:59:11 2014] [error] [client 127.0.0.1]   File "/Library/Python/2.7/site-packages/bottle.py", line 862, in _handle, referer: http://www.youtube.com/
[Thu Feb 20 09:59:11 2014] [error] [client 127.0.0.1]     return route.call(**args), referer: http://www.youtube.com/
[Thu Feb 20 09:59:11 2014] [error] [client 127.0.0.1]   File "/Library/Python/2.7/site-packages/bottle.py", line 1727, in wrapper, referer: http://www.youtube.com/
[Thu Feb 20 09:59:11 2014] [error] [client 127.0.0.1]     rv = callback(*a, **ka), referer: http://www.youtube.com/
[Thu Feb 20 09:59:11 2014] [error] [client 127.0.0.1]   File "/Users/mac/NLTK/jiebademo/jiebademo/wsgi.py", line 86, in extractFile_action, referer: http://www.youtube.com/
[Thu Feb 20 09:59:11 2014] [error] [client 127.0.0.1]     text = open('files/'+filename, 'rb').read(), referer: http://www.youtube.com/
[Thu Feb 20 09:59:11 2014] [error] [client 127.0.0.1] IOError: [Errno 2] No such file or directory: 'files/h.js', referer: http://www.youtube.com/
[Thu Feb 20 09:59:11 2014] [error] [client 127.0.0.1] Traceback (most recent call last):
[Thu Feb 20 09:59:11 2014] [error] [client 127.0.0.1]   File "/Library/Python/2.7/site-packages/bottle.py", line 862, in _handle
[Thu Feb 20 09:59:11 2014] [error] [client 127.0.0.1]     return route.call(**args)
[Thu Feb 20 09:59:11 2014] [error] [client 127.0.0.1]   File "/Library/Python/2.7/site-packages/bottle.py", line 1727, in wrapper
[Thu Feb 20 09:59:11 2014] [error] [client 127.0.0.1]     rv = callback(*a, **ka)
[Thu Feb 20 09:59:11 2014] [error] [client 127.0.0.1]   File "/Users/mac/NLTK/jiebademo/jiebademo/wsgi.py", line 86, in extractFile_action
[Thu Feb 20 09:59:11 2014] [error] [client 127.0.0.1]     text = open('files/'+filename, 'rb').read()
[Thu Feb 20 09:59:11 2014] [error] [client 127.0.0.1] IOError: [Errno 2] No such file or directory: 'files/favicon.ico'
[Thu Feb 20 10:00:38 2014] [error] [client 127.0.0.1] Traceback (most recent call last):
[Thu Feb 20 10:00:38 2014] [error] [client 127.0.0.1]   File "/Library/Python/2.7/site-packages/bottle.py", line 862, in _handle
[Thu Feb 20 10:00:38 2014] [error] [client 127.0.0.1]     return route.call(**args)
[Thu Feb 20 10:00:38 2014] [error] [client 127.0.0.1]   File "/Library/Python/2.7/site-packages/bottle.py", line 1727, in wrapper
[Thu Feb 20 10:00:38 2014] [error] [client 127.0.0.1]     rv = callback(*a, **ka)
[Thu Feb 20 10:00:38 2014] [error] [client 127.0.0.1]   File "/Users/mac/NLTK/jiebademo/jiebademo/wsgi.py", line 86, in extractFile_action
[Thu Feb 20 10:00:38 2014] [error] [client 127.0.0.1]     text = open('files/'+filename, 'rb').read()
[Thu Feb 20 10:00:38 2014] [error] [client 127.0.0.1] IOError: [Errno 2] No such file or directory: 'files/favicon.ico'
[Thu Feb 20 10:04:46 2014] [error] [client 127.0.0.1] Traceback (most recent call last):, referer: http://www.douban.com/
[Thu Feb 20 10:04:46 2014] [error] [client 127.0.0.1]   File "/Library/Python/2.7/site-packages/bottle.py", line 862, in _handle, referer: http://www.douban.com/
[Thu Feb 20 10:04:46 2014] [error] [client 127.0.0.1]     return route.call(**args), referer: http://www.douban.com/
[Thu Feb 20 10:04:46 2014] [error] [client 127.0.0.1]   File "/Library/Python/2.7/site-packages/bottle.py", line 1727, in wrapper, referer: http://www.douban.com/
[Thu Feb 20 10:04:46 2014] [error] [client 127.0.0.1]     rv = callback(*a, **ka), referer: http://www.douban.com/
[Thu Feb 20 10:04:46 2014] [error] [client 127.0.0.1]   File "/Users/mac/NLTK/jiebademo/jiebademo/wsgi.py", line 86, in extractFile_action, referer: http://www.douban.com/
[Thu Feb 20 10:04:46 2014] [error] [client 127.0.0.1]     text = open('files/'+filename, 'rb').read(), referer: http://www.douban.com/
[Thu Feb 20 10:04:46 2014] [error] [client 127.0.0.1] IOError: [Errno 2] No such file or directory: 'files/h.js', referer: http://www.douban.com/
[Thu Feb 20 10:05:00 2014] [error] [client 127.0.0.1] Traceback (most recent call last):, referer: http://www.douban.com/
[Thu Feb 20 10:05:00 2014] [error] [client 127.0.0.1]   File "/Library/Python/2.7/site-packages/bottle.py", line 862, in _handle, referer: http://www.douban.com/
[Thu Feb 20 10:05:00 2014] [error] [client 127.0.0.1]     return route.call(**args), referer: http://www.douban.com/
[Thu Feb 20 10:05:00 2014] [error] [client 127.0.0.1]   File "/Library/Python/2.7/site-packages/bottle.py", line 1727, in wrapper, referer: http://www.douban.com/
[Thu Feb 20 10:05:00 2014] [error] [client 127.0.0.1]     rv = callback(*a, **ka), referer: http://www.douban.com/
[Thu Feb 20 10:05:00 2014] [error] [client 127.0.0.1]   File "/Users/mac/NLTK/jiebademo/jiebademo/wsgi.py", line 86, in extractFile_action, referer: http://www.douban.com/
[Thu Feb 20 10:05:00 2014] [error] [client 127.0.0.1]     text = open('files/'+filename, 'rb').read(), referer: http://www.douban.com/
[Thu Feb 20 10:05:00 2014] [error] [client 127.0.0.1] IOError: [Errno 2] No such file or directory: 'files/h.js', referer: http://www.douban.com/
[Thu Feb 20 10:05:17 2014] [error] [client 127.0.0.1] Traceback (most recent call last):, referer: http://127.0.0.1:8087/
[Thu Feb 20 10:05:17 2014] [error] [client 127.0.0.1]   File "/Library/Python/2.7/site-packages/bottle.py", line 862, in _handle, referer: http://127.0.0.1:8087/
[Thu Feb 20 10:05:17 2014] [error] [client 127.0.0.1]     return route.call(**args), referer: http://127.0.0.1:8087/
[Thu Feb 20 10:05:17 2014] [error] [client 127.0.0.1]   File "/Library/Python/2.7/site-packages/bottle.py", line 1727, in wrapper, referer: http://127.0.0.1:8087/
[Thu Feb 20 10:05:17 2014] [error] [client 127.0.0.1]     rv = callback(*a, **ka), referer: http://127.0.0.1:8087/
[Thu Feb 20 10:05:17 2014] [error] [client 127.0.0.1]   File "/Users/mac/NLTK/jiebademo/jiebademo/wsgi.py", line 86, in extractFile_action, referer: http://127.0.0.1:8087/
[Thu Feb 20 10:05:17 2014] [error] [client 127.0.0.1]     text = open('files/'+filename, 'rb').read(), referer: http://127.0.0.1:8087/
[Thu Feb 20 10:05:17 2014] [error] [client 127.0.0.1] IOError: [Errno 2] No such file or directory: 'files/h.js', referer: http://127.0.0.1:8087/
[Thu Feb 20 10:05:19 2014] [error] [client 127.0.0.1] Traceback (most recent call last):, referer: http://localhost:8087/
[Thu Feb 20 10:05:19 2014] [error] [client 127.0.0.1]   File "/Library/Python/2.7/site-packages/bottle.py", line 862, in _handle, referer: http://localhost:8087/
[Thu Feb 20 10:05:19 2014] [error] [client 127.0.0.1]     return route.call(**args), referer: http://localhost:8087/
[Thu Feb 20 10:05:19 2014] [error] [client 127.0.0.1]   File "/Library/Python/2.7/site-packages/bottle.py", line 1727, in wrapper, referer: http://localhost:8087/
[Thu Feb 20 10:05:19 2014] [error] [client 127.0.0.1]     rv = callback(*a, **ka), referer: http://localhost:8087/
[Thu Feb 20 10:05:19 2014] [error] [client 127.0.0.1]   File "/Users/mac/NLTK/jiebademo/jiebademo/wsgi.py", line 86, in extractFile_action, referer: http://localhost:8087/
[Thu Feb 20 10:05:19 2014] [error] [client 127.0.0.1]     text = open('files/'+filename, 'rb').read(), referer: http://localhost:8087/
[Thu Feb 20 10:05:19 2014] [error] [client 127.0.0.1] IOError: [Errno 2] No such file or directory: 'files/h.js', referer: http://localhost:8087/
[Thu Feb 20 10:05:19 2014] [error] [client 127.0.0.1] Traceback (most recent call last):, referer: http://www.baidu.com/
[Thu Feb 20 10:05:19 2014] [error] [client 127.0.0.1]   File "/Library/Python/2.7/site-packages/bottle.py", line 862, in _handle, referer: http://www.baidu.com/
[Thu Feb 20 10:05:19 2014] [error] [client 127.0.0.1]     return route.call(**args), referer: http://www.baidu.com/
[Thu Feb 20 10:05:19 2014] [error] [client 127.0.0.1]   File "/Library/Python/2.7/site-packages/bottle.py", line 1727, in wrapper, referer: http://www.baidu.com/
[Thu Feb 20 10:05:19 2014] [error] [client 127.0.0.1]     rv = callback(*a, **ka), referer: http://www.baidu.com/
[Thu Feb 20 10:05:19 2014] [error] [client 127.0.0.1]   File "/Users/mac/NLTK/jiebademo/jiebademo/wsgi.py", line 86, in extractFile_action, referer: http://www.baidu.com/
[Thu Feb 20 10:05:19 2014] [error] [client 127.0.0.1]     text = open('files/'+filename, 'rb').read(), referer: http://www.baidu.com/
[Thu Feb 20 10:05:19 2014] [error] [client 127.0.0.1] IOError: [Errno 2] No such file or directory: 'files/h.js', referer: http://www.baidu.com/
[Thu Feb 20 10:05:19 2014] [error] [client 127.0.0.1] Traceback (most recent call last):, referer: http://www.baidu.com/
[Thu Feb 20 10:05:19 2014] [error] [client 127.0.0.1]   File "/Library/Python/2.7/site-packages/bottle.py", line 862, in _handle, referer: http://www.baidu.com/
[Thu Feb 20 10:05:19 2014] [error] [client 127.0.0.1]     return route.call(**args), referer: http://www.baidu.com/
[Thu Feb 20 10:05:19 2014] [error] [client 127.0.0.1]   File "/Library/Python/2.7/site-packages/bottle.py", line 1727, in wrapper, referer: http://www.baidu.com/
[Thu Feb 20 10:05:19 2014] [error] [client 127.0.0.1]     rv = callback(*a, **ka), referer: http://www.baidu.com/
[Thu Feb 20 10:05:19 2014] [error] [client 127.0.0.1]   File "/Users/mac/NLTK/jiebademo/jiebademo/wsgi.py", line 86, in extractFile_action, referer: http://www.baidu.com/
[Thu Feb 20 10:05:19 2014] [error] [client 127.0.0.1]     text = open('files/'+filename, 'rb').read(), referer: http://www.baidu.com/
[Thu Feb 20 10:05:19 2014] [error] [client 127.0.0.1] IOError: [Errno 2] No such file or directory: 'files/favicon.ico', referer: http://www.baidu.com/
[Thu Feb 20 10:06:39 2014] [error] [client 127.0.0.1] Traceback (most recent call last):, referer: http://www.baidu.com/extract
[Thu Feb 20 10:06:39 2014] [error] [client 127.0.0.1]   File "/Library/Python/2.7/site-packages/bottle.py", line 862, in _handle, referer: http://www.baidu.com/extract
[Thu Feb 20 10:06:39 2014] [error] [client 127.0.0.1]     return route.call(**args), referer: http://www.baidu.com/extract
[Thu Feb 20 10:06:39 2014] [error] [client 127.0.0.1]   File "/Library/Python/2.7/site-packages/bottle.py", line 1727, in wrapper, referer: http://www.baidu.com/extract
[Thu Feb 20 10:06:39 2014] [error] [client 127.0.0.1]     rv = callback(*a, **ka), referer: http://www.baidu.com/extract
[Thu Feb 20 10:06:39 2014] [error] [client 127.0.0.1]   File "/Users/mac/NLTK/jiebademo/jiebademo/wsgi.py", line 86, in extractFile_action, referer: http://www.baidu.com/extract
[Thu Feb 20 10:06:39 2014] [error] [client 127.0.0.1]     text = open('files/'+filename, 'rb').read(), referer: http://www.baidu.com/extract
[Thu Feb 20 10:06:39 2014] [error] [client 127.0.0.1] IOError: [Errno 2] No such file or directory: 'files/h.js', referer: http://www.baidu.com/extract
[Thu Feb 20 10:06:50 2014] [error] [client 127.0.0.1] Traceback (most recent call last):, referer: http://www.baidu.com/extract
[Thu Feb 20 10:06:50 2014] [error] [client 127.0.0.1]   File "/Library/Python/2.7/site-packages/bottle.py", line 862, in _handle, referer: http://www.baidu.com/extract
[Thu Feb 20 10:06:50 2014] [error] [client 127.0.0.1]     return route.call(**args), referer: http://www.baidu.com/extract
[Thu Feb 20 10:06:50 2014] [error] [client 127.0.0.1]   File "/Library/Python/2.7/site-packages/bottle.py", line 1727, in wrapper, referer: http://www.baidu.com/extract
[Thu Feb 20 10:06:50 2014] [error] [client 127.0.0.1]     rv = callback(*a, **ka), referer: http://www.baidu.com/extract
[Thu Feb 20 10:06:50 2014] [error] [client 127.0.0.1]   File "/Users/mac/NLTK/jiebademo/jiebademo/wsgi.py", line 86, in extractFile_action, referer: http://www.baidu.com/extract
[Thu Feb 20 10:06:50 2014] [error] [client 127.0.0.1]     text = open('files/'+filename, 'rb').read(), referer: http://www.baidu.com/extract
[Thu Feb 20 10:06:50 2014] [error] [client 127.0.0.1] IOError: [Errno 2] No such file or directory: 'files/h.js', referer: http://www.baidu.com/extract
[Thu Feb 20 10:08:36 2014] [error] [client 127.0.0.1] Traceback (most recent call last):, referer: http://www.douban.com/extract
[Thu Feb 20 10:08:36 2014] [error] [client 127.0.0.1]   File "/Library/Python/2.7/site-packages/bottle.py", line 862, in _handle, referer: http://www.douban.com/extract
[Thu Feb 20 10:08:36 2014] [error] [client 127.0.0.1]     return route.call(**args), referer: http://www.douban.com/extract
[Thu Feb 20 10:08:36 2014] [error] [client 127.0.0.1]   File "/Library/Python/2.7/site-packages/bottle.py", line 1727, in wrapper, referer: http://www.douban.com/extract
[Thu Feb 20 10:08:36 2014] [error] [client 127.0.0.1]     rv = callback(*a, **ka), referer: http://www.douban.com/extract
[Thu Feb 20 10:08:36 2014] [error] [client 127.0.0.1]   File "/Users/mac/NLTK/jiebademo/jiebademo/wsgi.py", line 86, in extractFile_action, referer: http://www.douban.com/extract
[Thu Feb 20 10:08:36 2014] [error] [client 127.0.0.1]     text = open('files/'+filename, 'rb').read(), referer: http://www.douban.com/extract
[Thu Feb 20 10:08:36 2014] [error] [client 127.0.0.1] IOError: [Errno 2] No such file or directory: 'files/h.js', referer: http://www.douban.com/extract
[Thu Feb 20 10:08:47 2014] [error] [client 127.0.0.1] Traceback (most recent call last):, referer: http://www.douban.com/extract
[Thu Feb 20 10:08:47 2014] [error] [client 127.0.0.1]   File "/Library/Python/2.7/site-packages/bottle.py", line 862, in _handle, referer: http://www.douban.com/extract
[Thu Feb 20 10:08:47 2014] [error] [client 127.0.0.1]     return route.call(**args), referer: http://www.douban.com/extract
[Thu Feb 20 10:08:47 2014] [error] [client 127.0.0.1]   File "/Library/Python/2.7/site-packages/bottle.py", line 1727, in wrapper, referer: http://www.douban.com/extract
[Thu Feb 20 10:08:47 2014] [error] [client 127.0.0.1]     rv = callback(*a, **ka), referer: http://www.douban.com/extract
[Thu Feb 20 10:08:47 2014] [error] [client 127.0.0.1]   File "/Users/mac/NLTK/jiebademo/jiebademo/wsgi.py", line 86, in extractFile_action, referer: http://www.douban.com/extract
[Thu Feb 20 10:08:47 2014] [error] [client 127.0.0.1]     text = open('files/'+filename, 'rb').read(), referer: http://www.douban.com/extract
[Thu Feb 20 10:08:47 2014] [error] [client 127.0.0.1] IOError: [Errno 2] No such file or directory: 'files/h.js', referer: http://www.douban.com/extract
[Thu Feb 20 10:09:27 2014] [error] [client 127.0.0.1] Traceback (most recent call last):, referer: http://www.douban.com/extract
[Thu Feb 20 10:09:27 2014] [error] [client 127.0.0.1]   File "/Library/Python/2.7/site-packages/bottle.py", line 862, in _handle, referer: http://www.douban.com/extract
[Thu Feb 20 10:09:27 2014] [error] [client 127.0.0.1]     return route.call(**args), referer: http://www.douban.com/extract
[Thu Feb 20 10:09:27 2014] [error] [client 127.0.0.1]   File "/Library/Python/2.7/site-packages/bottle.py", line 1727, in wrapper, referer: http://www.douban.com/extract
[Thu Feb 20 10:09:27 2014] [error] [client 127.0.0.1]     rv = callback(*a, **ka), referer: http://www.douban.com/extract
[Thu Feb 20 10:09:27 2014] [error] [client 127.0.0.1]   File "/Users/mac/NLTK/jiebademo/jiebademo/wsgi.py", line 86, in extractFile_action, referer: http://www.douban.com/extract
[Thu Feb 20 10:09:27 2014] [error] [client 127.0.0.1]     text = open('files/'+filename, 'rb').read(), referer: http://www.douban.com/extract
[Thu Feb 20 10:09:27 2014] [error] [client 127.0.0.1] IOError: [Errno 2] No such file or directory: 'files/h.js', referer: http://www.douban.com/extract
[Thu Feb 20 10:09:44 2014] [error] [client 127.0.0.1] Traceback (most recent call last):, referer: http://www.douban.com/extract
[Thu Feb 20 10:09:44 2014] [error] [client 127.0.0.1]   File "/Library/Python/2.7/site-packages/bottle.py", line 862, in _handle, referer: http://www.douban.com/extract
[Thu Feb 20 10:09:44 2014] [error] [client 127.0.0.1]     return route.call(**args), referer: http://www.douban.com/extract
[Thu Feb 20 10:09:44 2014] [error] [client 127.0.0.1]   File "/Library/Python/2.7/site-packages/bottle.py", line 1727, in wrapper, referer: http://www.douban.com/extract
[Thu Feb 20 10:09:44 2014] [error] [client 127.0.0.1]     rv = callback(*a, **ka), referer: http://www.douban.com/extract
[Thu Feb 20 10:09:44 2014] [error] [client 127.0.0.1]   File "/Users/mac/NLTK/jiebademo/jiebademo/wsgi.py", line 86, in extractFile_action, referer: http://www.douban.com/extract
[Thu Feb 20 10:09:44 2014] [error] [client 127.0.0.1]     text = open('files/'+filename, 'rb').read(), referer: http://www.douban.com/extract
[Thu Feb 20 10:09:44 2014] [error] [client 127.0.0.1] IOError: [Errno 2] No such file or directory: 'files/h.js', referer: http://www.douban.com/extract
[Thu Feb 20 10:09:50 2014] [error] [client 127.0.0.1] Traceback (most recent call last):, referer: http://www.douban.com/extract
[Thu Feb 20 10:09:50 2014] [error] [client 127.0.0.1]   File "/Library/Python/2.7/site-packages/bottle.py", line 862, in _handle, referer: http://www.douban.com/extract
[Thu Feb 20 10:09:50 2014] [error] [client 127.0.0.1]     return route.call(**args), referer: http://www.douban.com/extract
[Thu Feb 20 10:09:50 2014] [error] [client 127.0.0.1]   File "/Library/Python/2.7/site-packages/bottle.py", line 1727, in wrapper, referer: http://www.douban.com/extract
[Thu Feb 20 10:09:50 2014] [error] [client 127.0.0.1]     rv = callback(*a, **ka), referer: http://www.douban.com/extract
[Thu Feb 20 10:09:50 2014] [error] [client 127.0.0.1]   File "/Users/mac/NLTK/jiebademo/jiebademo/wsgi.py", line 86, in extractFile_action, referer: http://www.douban.com/extract
[Thu Feb 20 10:09:50 2014] [error] [client 127.0.0.1]     text = open('files/'+filename, 'rb').read(), referer: http://www.douban.com/extract
[Thu Feb 20 10:09:50 2014] [error] [client 127.0.0.1] IOError: [Errno 2] No such file or directory: 'files/h.js', referer: http://www.douban.com/extract
[Thu Feb 20 10:11:09 2014] [error] [client 127.0.0.1] Traceback (most recent call last):, referer: http://www.douban.com/wangyangming_mid.txt
[Thu Feb 20 10:11:09 2014] [error] [client 127.0.0.1]   File "/Library/Python/2.7/site-packages/bottle.py", line 862, in _handle, referer: http://www.douban.com/wangyangming_mid.txt
[Thu Feb 20 10:11:09 2014] [error] [client 127.0.0.1]     return route.call(**args), referer: http://www.douban.com/wangyangming_mid.txt
[Thu Feb 20 10:11:09 2014] [error] [client 127.0.0.1]   File "/Library/Python/2.7/site-packages/bottle.py", line 1727, in wrapper, referer: http://www.douban.com/wangyangming_mid.txt
[Thu Feb 20 10:11:09 2014] [error] [client 127.0.0.1]     rv = callback(*a, **ka), referer: http://www.douban.com/wangyangming_mid.txt
[Thu Feb 20 10:11:09 2014] [error] [client 127.0.0.1]   File "/Users/mac/NLTK/jiebademo/jiebademo/wsgi.py", line 86, in extractFile_action, referer: http://www.douban.com/wangyangming_mid.txt
[Thu Feb 20 10:11:09 2014] [error] [client 127.0.0.1]     text = open('files/'+filename, 'rb').read(), referer: http://www.douban.com/wangyangming_mid.txt
[Thu Feb 20 10:11:09 2014] [error] [client 127.0.0.1] IOError: [Errno 2] No such file or directory: 'files/h.js', referer: http://www.douban.com/wangyangming_mid.txt
[Thu Feb 20 10:11:45 2014] [error] [client 127.0.0.1] Traceback (most recent call last):, referer: http://www.douban.com/extract
[Thu Feb 20 10:11:45 2014] [error] [client 127.0.0.1]   File "/Library/Python/2.7/site-packages/bottle.py", line 862, in _handle, referer: http://www.douban.com/extract
[Thu Feb 20 10:11:45 2014] [error] [client 127.0.0.1]     return route.call(**args), referer: http://www.douban.com/extract
[Thu Feb 20 10:11:45 2014] [error] [client 127.0.0.1]   File "/Library/Python/2.7/site-packages/bottle.py", line 1727, in wrapper, referer: http://www.douban.com/extract
[Thu Feb 20 10:11:45 2014] [error] [client 127.0.0.1]     rv = callback(*a, **ka), referer: http://www.douban.com/extract
[Thu Feb 20 10:11:45 2014] [error] [client 127.0.0.1]   File "/Users/mac/NLTK/jiebademo/jiebademo/wsgi.py", line 86, in extractFile_action, referer: http://www.douban.com/extract
[Thu Feb 20 10:11:45 2014] [error] [client 127.0.0.1]     text = open('files/'+filename, 'rb').read(), referer: http://www.douban.com/extract
[Thu Feb 20 10:11:45 2014] [error] [client 127.0.0.1] IOError: [Errno 2] No such file or directory: 'files/h.js', referer: http://www.douban.com/extract
[Thu Feb 20 10:12:37 2014] [error] [client 127.0.0.1] Traceback (most recent call last):, referer: http://www.douban.com/
[Thu Feb 20 10:12:37 2014] [error] [client 127.0.0.1]   File "/Library/Python/2.7/site-packages/bottle.py", line 862, in _handle, referer: http://www.douban.com/
[Thu Feb 20 10:12:37 2014] [error] [client 127.0.0.1]     return route.call(**args), referer: http://www.douban.com/
[Thu Feb 20 10:12:37 2014] [error] [client 127.0.0.1]   File "/Library/Python/2.7/site-packages/bottle.py", line 1727, in wrapper, referer: http://www.douban.com/
[Thu Feb 20 10:12:37 2014] [error] [client 127.0.0.1]     rv = callback(*a, **ka), referer: http://www.douban.com/
[Thu Feb 20 10:12:37 2014] [error] [client 127.0.0.1]   File "/Users/mac/NLTK/jiebademo/jiebademo/wsgi.py", line 86, in extractFile_action, referer: http://www.douban.com/
[Thu Feb 20 10:12:37 2014] [error] [client 127.0.0.1]     text = open('files/'+filename, 'rb').read(), referer: http://www.douban.com/
[Thu Feb 20 10:12:37 2014] [error] [client 127.0.0.1] IOError: [Errno 2] No such file or directory: 'files/h.js', referer: http://www.douban.com/
[Thu Feb 20 10:13:25 2014] [error] [client 127.0.0.1] Traceback (most recent call last):, referer: http://www.douban.com/extract
[Thu Feb 20 10:13:25 2014] [error] [client 127.0.0.1]   File "/Library/Python/2.7/site-packages/bottle.py", line 862, in _handle, referer: http://www.douban.com/extract
[Thu Feb 20 10:13:25 2014] [error] [client 127.0.0.1]     return route.call(**args), referer: http://www.douban.com/extract
[Thu Feb 20 10:13:25 2014] [error] [client 127.0.0.1]   File "/Library/Python/2.7/site-packages/bottle.py", line 1727, in wrapper, referer: http://www.douban.com/extract
[Thu Feb 20 10:13:25 2014] [error] [client 127.0.0.1]     rv = callback(*a, **ka), referer: http://www.douban.com/extract
[Thu Feb 20 10:13:25 2014] [error] [client 127.0.0.1]   File "/Users/mac/NLTK/jiebademo/jiebademo/wsgi.py", line 86, in extractFile_action, referer: http://www.douban.com/extract
[Thu Feb 20 10:13:25 2014] [error] [client 127.0.0.1]     text = open('files/'+filename, 'rb').read(), referer: http://www.douban.com/extract
[Thu Feb 20 10:13:25 2014] [error] [client 127.0.0.1] IOError: [Errno 2] No such file or directory: 'files/h.js', referer: http://www.douban.com/extract
[Thu Feb 20 10:13:34 2014] [error] [client 127.0.0.1] Traceback (most recent call last):, referer: http://www.douban.com/extract
[Thu Feb 20 10:13:34 2014] [error] [client 127.0.0.1]   File "/Library/Python/2.7/site-packages/bottle.py", line 862, in _handle, referer: http://www.douban.com/extract
[Thu Feb 20 10:13:34 2014] [error] [client 127.0.0.1]     return route.call(**args), referer: http://www.douban.com/extract
[Thu Feb 20 10:13:34 2014] [error] [client 127.0.0.1]   File "/Library/Python/2.7/site-packages/bottle.py", line 1727, in wrapper, referer: http://www.douban.com/extract
[Thu Feb 20 10:13:34 2014] [error] [client 127.0.0.1]     rv = callback(*a, **ka), referer: http://www.douban.com/extract
[Thu Feb 20 10:13:34 2014] [error] [client 127.0.0.1]   File "/Users/mac/NLTK/jiebademo/jiebademo/wsgi.py", line 86, in extractFile_action, referer: http://www.douban.com/extract
[Thu Feb 20 10:13:34 2014] [error] [client 127.0.0.1]     text = open('files/'+filename, 'rb').read(), referer: http://www.douban.com/extract
[Thu Feb 20 10:13:34 2014] [error] [client 127.0.0.1] IOError: [Errno 2] No such file or directory: 'files/h.js', referer: http://www.douban.com/extract
[Thu Feb 20 10:14:23 2014] [error] [client 127.0.0.1] Traceback (most recent call last):, referer: http://www.douban.com/extract
[Thu Feb 20 10:14:23 2014] [error] [client 127.0.0.1]   File "/Library/Python/2.7/site-packages/bottle.py", line 862, in _handle, referer: http://www.douban.com/extract
[Thu Feb 20 10:14:23 2014] [error] [client 127.0.0.1]     return route.call(**args), referer: http://www.douban.com/extract
[Thu Feb 20 10:14:23 2014] [error] [client 127.0.0.1]   File "/Library/Python/2.7/site-packages/bottle.py", line 1727, in wrapper, referer: http://www.douban.com/extract
[Thu Feb 20 10:14:23 2014] [error] [client 127.0.0.1]     rv = callback(*a, **ka), referer: http://www.douban.com/extract
[Thu Feb 20 10:14:23 2014] [error] [client 127.0.0.1]   File "/Users/mac/NLTK/jiebademo/jiebademo/wsgi.py", line 86, in extractFile_action, referer: http://www.douban.com/extract
[Thu Feb 20 10:14:23 2014] [error] [client 127.0.0.1]     text = open('files/'+filename, 'rb').read(), referer: http://www.douban.com/extract
[Thu Feb 20 10:14:23 2014] [error] [client 127.0.0.1] IOError: [Errno 2] No such file or directory: 'files/h.js', referer: http://www.douban.com/extract
[Thu Feb 20 10:15:59 2014] [error] [client 127.0.0.1] Traceback (most recent call last):
[Thu Feb 20 10:15:59 2014] [error] [client 127.0.0.1]   File "/Library/Python/2.7/site-packages/bottle.py", line 862, in _handle
[Thu Feb 20 10:15:59 2014] [error] [client 127.0.0.1]     return route.call(**args)
[Thu Feb 20 10:15:59 2014] [error] [client 127.0.0.1]   File "/Library/Python/2.7/site-packages/bottle.py", line 1727, in wrapper
[Thu Feb 20 10:15:59 2014] [error] [client 127.0.0.1]     rv = callback(*a, **ka)
[Thu Feb 20 10:15:59 2014] [error] [client 127.0.0.1]   File "/Users/mac/NLTK/jiebademo/jiebademo/wsgi.py", line 86, in extractFile_action
[Thu Feb 20 10:15:59 2014] [error] [client 127.0.0.1]     def extractFile_action(filename):
[Thu Feb 20 10:15:59 2014] [error] [client 127.0.0.1] IOError: [Errno 2] No such file or directory: 'files/MFYwVKADAgEAME0wSzBJMAkGBSsOAwIaBQAEFO1Ird3LewDiDoQqqbQJ8awwNM+WBBRQ6nOJ2yn7EI+e5QEg1N55mUiD9wIQC2f1zy6GM41rRG25cXpYwA=='
[Thu Feb 20 10:15:59 2014] [error] [client 127.0.0.1] Traceback (most recent call last):
[Thu Feb 20 10:15:59 2014] [error] [client 127.0.0.1]   File "/Library/Python/2.7/site-packages/bottle.py", line 862, in _handle
[Thu Feb 20 10:15:59 2014] [error] [client 127.0.0.1]     return route.call(**args)
[Thu Feb 20 10:15:59 2014] [error] [client 127.0.0.1]   File "/Library/Python/2.7/site-packages/bottle.py", line 1727, in wrapper
[Thu Feb 20 10:15:59 2014] [error] [client 127.0.0.1]     rv = callback(*a, **ka)
[Thu Feb 20 10:15:59 2014] [error] [client 127.0.0.1]   File "/Users/mac/NLTK/jiebademo/jiebademo/wsgi.py", line 86, in extractFile_action
[Thu Feb 20 10:15:59 2014] [error] [client 127.0.0.1]     def extractFile_action(filename):
[Thu Feb 20 10:15:59 2014] [error] [client 127.0.0.1] IOError: [Errno 2] No such file or directory: 'files/ca3-g22.crl'
[Thu Feb 20 10:15:59 2014] [error] [client 127.0.0.1] Traceback (most recent call last):
[Thu Feb 20 10:15:59 2014] [error] [client 127.0.0.1]   File "/Library/Python/2.7/site-packages/bottle.py", line 862, in _handle
[Thu Feb 20 10:15:59 2014] [error] [client 127.0.0.1]     return route.call(**args)
[Thu Feb 20 10:15:59 2014] [error] [client 127.0.0.1]   File "/Library/Python/2.7/site-packages/bottle.py", line 1727, in wrapper
[Thu Feb 20 10:15:59 2014] [error] [client 127.0.0.1]     rv = callback(*a, **ka)
[Thu Feb 20 10:15:59 2014] [error] [client 127.0.0.1]   File "/Users/mac/NLTK/jiebademo/jiebademo/wsgi.py", line 86, in extractFile_action
[Thu Feb 20 10:15:59 2014] [error] [client 127.0.0.1]     def extractFile_action(filename):
[Thu Feb 20 10:15:59 2014] [error] [client 127.0.0.1] IOError: [Errno 2] No such file or directory: 'files/ca3-g22.crl'
[Thu Feb 20 10:15:59 2014] [error] [client 127.0.0.1] Traceback (most recent call last):
[Thu Feb 20 10:15:59 2014] [error] [client 127.0.0.1]   File "/Library/Python/2.7/site-packages/bottle.py", line 862, in _handle
[Thu Feb 20 10:15:59 2014] [error] [client 127.0.0.1]     return route.call(**args)
[Thu Feb 20 10:15:59 2014] [error] [client 127.0.0.1]   File "/Library/Python/2.7/site-packages/bottle.py", line 1727, in wrapper
[Thu Feb 20 10:15:59 2014] [error] [client 127.0.0.1]     rv = callback(*a, **ka)
[Thu Feb 20 10:15:59 2014] [error] [client 127.0.0.1]   File "/Users/mac/NLTK/jiebademo/jiebademo/wsgi.py", line 86, in extractFile_action
[Thu Feb 20 10:15:59 2014] [error] [client 127.0.0.1]     def extractFile_action(filename):
[Thu Feb 20 10:15:59 2014] [error] [client 127.0.0.1] IOError: [Errno 2] No such file or directory: 'files/ca3-g22.crl'
[Thu Feb 20 10:15:59 2014] [error] [client 127.0.0.1] Traceback (most recent call last):
[Thu Feb 20 10:15:59 2014] [error] [client 127.0.0.1]   File "/Library/Python/2.7/site-packages/bottle.py", line 862, in _handle
[Thu Feb 20 10:15:59 2014] [error] [client 127.0.0.1]     return route.call(**args)
[Thu Feb 20 10:15:59 2014] [error] [client 127.0.0.1]   File "/Library/Python/2.7/site-packages/bottle.py", line 1727, in wrapper
[Thu Feb 20 10:15:59 2014] [error] [client 127.0.0.1]     rv = callback(*a, **ka)
[Thu Feb 20 10:15:59 2014] [error] [client 127.0.0.1]   File "/Users/mac/NLTK/jiebademo/jiebademo/wsgi.py", line 86, in extractFile_action
[Thu Feb 20 10:15:59 2014] [error] [client 127.0.0.1]     def extractFile_action(filename):
[Thu Feb 20 10:15:59 2014] [error] [client 127.0.0.1] IOError: [Errno 2] No such file or directory: 'files/ca3-g22.crl'
[Thu Feb 20 10:15:59 2014] [error] [client 127.0.0.1] Traceback (most recent call last):
[Thu Feb 20 10:15:59 2014] [error] [client 127.0.0.1]   File "/Library/Python/2.7/site-packages/bottle.py", line 862, in _handle
[Thu Feb 20 10:15:59 2014] [error] [client 127.0.0.1]     return route.call(**args)
[Thu Feb 20 10:15:59 2014] [error] [client 127.0.0.1]   File "/Library/Python/2.7/site-packages/bottle.py", line 1727, in wrapper
[Thu Feb 20 10:15:59 2014] [error] [client 127.0.0.1]     rv = callback(*a, **ka)
[Thu Feb 20 10:15:59 2014] [error] [client 127.0.0.1]   File "/Users/mac/NLTK/jiebademo/jiebademo/wsgi.py", line 86, in extractFile_action
[Thu Feb 20 10:15:59 2014] [error] [client 127.0.0.1]     def extractFile_action(filename):
[Thu Feb 20 10:15:59 2014] [error] [client 127.0.0.1] IOError: [Errno 2] No such file or directory: 'files/DigiCertHighAssuranceEVRootCA.crl'
[Thu Feb 20 10:15:59 2014] [error] [client 127.0.0.1] Traceback (most recent call last):
[Thu Feb 20 10:15:59 2014] [error] [client 127.0.0.1]   File "/Library/Python/2.7/site-packages/bottle.py", line 862, in _handle
[Thu Feb 20 10:15:59 2014] [error] [client 127.0.0.1]     return route.call(**args)
[Thu Feb 20 10:15:59 2014] [error] [client 127.0.0.1]   File "/Library/Python/2.7/site-packages/bottle.py", line 1727, in wrapper
[Thu Feb 20 10:15:59 2014] [error] [client 127.0.0.1]     rv = callback(*a, **ka)
[Thu Feb 20 10:15:59 2014] [error] [client 127.0.0.1]   File "/Users/mac/NLTK/jiebademo/jiebademo/wsgi.py", line 86, in extractFile_action
[Thu Feb 20 10:15:59 2014] [error] [client 127.0.0.1]     def extractFile_action(filename):
[Thu Feb 20 10:15:59 2014] [error] [client 127.0.0.1] IOError: [Errno 2] No such file or directory: 'files/DigiCertHighAssuranceEVRootCA.crl'
[Thu Feb 20 10:15:59 2014] [error] [client 127.0.0.1] Traceback (most recent call last):
[Thu Feb 20 10:15:59 2014] [error] [client 127.0.0.1]   File "/Library/Python/2.7/site-packages/bottle.py", line 862, in _handle
[Thu Feb 20 10:15:59 2014] [error] [client 127.0.0.1]     return route.call(**args)
[Thu Feb 20 10:15:59 2014] [error] [client 127.0.0.1]   File "/Library/Python/2.7/site-packages/bottle.py", line 1727, in wrapper
[Thu Feb 20 10:15:59 2014] [error] [client 127.0.0.1]     rv = callback(*a, **ka)
[Thu Feb 20 10:15:59 2014] [error] [client 127.0.0.1]   File "/Users/mac/NLTK/jiebademo/jiebademo/wsgi.py", line 86, in extractFile_action
[Thu Feb 20 10:15:59 2014] [error] [client 127.0.0.1]     def extractFile_action(filename):
[Thu Feb 20 10:15:59 2014] [error] [client 127.0.0.1] IOError: [Errno 2] No such file or directory: 'files/DigiCertHighAssuranceEVRootCA.crl'
[Thu Feb 20 10:16:00 2014] [error] [client 127.0.0.1] Traceback (most recent call last):
[Thu Feb 20 10:16:00 2014] [error] [client 127.0.0.1]   File "/Library/Python/2.7/site-packages/bottle.py", line 862, in _handle
[Thu Feb 20 10:16:00 2014] [error] [client 127.0.0.1]     return route.call(**args)
[Thu Feb 20 10:16:00 2014] [error] [client 127.0.0.1]   File "/Library/Python/2.7/site-packages/bottle.py", line 1727, in wrapper
[Thu Feb 20 10:16:00 2014] [error] [client 127.0.0.1]     rv = callback(*a, **ka)
[Thu Feb 20 10:16:00 2014] [error] [client 127.0.0.1]   File "/Users/mac/NLTK/jiebademo/jiebademo/wsgi.py", line 86, in extractFile_action
[Thu Feb 20 10:16:00 2014] [error] [client 127.0.0.1]     def extractFile_action(filename):
[Thu Feb 20 10:16:00 2014] [error] [client 127.0.0.1] IOError: [Errno 2] No such file or directory: 'files/DigiCertHighAssuranceEVRootCA.crl'
[Sun Feb 23 11:30:28 2014] [error] [client 127.0.0.1] Traceback (most recent call last):
[Sun Feb 23 11:30:28 2014] [error] [client 127.0.0.1]   File "/Library/Python/2.7/site-packages/bottle.py", line 862, in _handle
[Sun Feb 23 11:30:28 2014] [error] [client 127.0.0.1]     return route.call(**args)
[Sun Feb 23 11:30:28 2014] [error] [client 127.0.0.1]   File "/Library/Python/2.7/site-packages/bottle.py", line 1727, in wrapper
[Sun Feb 23 11:30:28 2014] [error] [client 127.0.0.1]     rv = callback(*a, **ka)
[Sun Feb 23 11:30:28 2014] [error] [client 127.0.0.1]   File "/Users/mac/NLTK/jiebademo/jiebademo/wsgi.py", line 87, in extractFile_action
[Sun Feb 23 11:30:28 2014] [error] [client 127.0.0.1]     text = open('files/'+filename, 'rb').read()
[Sun Feb 23 11:30:28 2014] [error] [client 127.0.0.1] IOError: [Errno 2] No such file or directory: 'files/favicon.ico'
[Sun Feb 23 12:02:34 2014] [error] [client 127.0.0.1] Traceback (most recent call last):
[Sun Feb 23 12:02:34 2014] [error] [client 127.0.0.1]   File "/Library/Python/2.7/site-packages/bottle.py", line 862, in _handle
[Sun Feb 23 12:02:34 2014] [error] [client 127.0.0.1]     return route.call(**args)
[Sun Feb 23 12:02:34 2014] [error] [client 127.0.0.1]   File "/Library/Python/2.7/site-packages/bottle.py", line 1727, in wrapper
[Sun Feb 23 12:02:34 2014] [error] [client 127.0.0.1]     rv = callback(*a, **ka)
[Sun Feb 23 12:02:34 2014] [error] [client 127.0.0.1]   File "/Users/mac/NLTK/jiebademo/jiebademo/wsgi.py", line 87, in extractFile_action
[Sun Feb 23 12:02:34 2014] [error] [client 127.0.0.1]     text = open('files/'+filename, 'rb').read()
[Sun Feb 23 12:02:34 2014] [error] [client 127.0.0.1] IOError: [Errno 2] No such file or directory: 'files/favicon.ico'
[Sun Feb 23 12:03:02 2014] [error] [client 127.0.0.1] Traceback (most recent call last):
[Sun Feb 23 12:03:02 2014] [error] [client 127.0.0.1]   File "/Library/Python/2.7/site-packages/bottle.py", line 862, in _handle
[Sun Feb 23 12:03:02 2014] [error] [client 127.0.0.1]     return route.call(**args)
[Sun Feb 23 12:03:02 2014] [error] [client 127.0.0.1]   File "/Library/Python/2.7/site-packages/bottle.py", line 1727, in wrapper
[Sun Feb 23 12:03:02 2014] [error] [client 127.0.0.1]     rv = callback(*a, **ka)
[Sun Feb 23 12:03:02 2014] [error] [client 127.0.0.1]   File "/Users/mac/NLTK/jiebademo/jiebademo/wsgi.py", line 87, in extractFile_action
[Sun Feb 23 12:03:02 2014] [error] [client 127.0.0.1]     text = open('files/'+filename, 'rb').read()
[Sun Feb 23 12:03:02 2014] [error] [client 127.0.0.1] IOError: [Errno 2] No such file or directory: 'files/favicon.ico'
[Sun Feb 23 12:03:02 2014] [error] [client 127.0.0.1] Traceback (most recent call last):
[Sun Feb 23 12:03:02 2014] [error] [client 127.0.0.1]   File "/Library/Python/2.7/site-packages/bottle.py", line 862, in _handle
[Sun Feb 23 12:03:02 2014] [error] [client 127.0.0.1]     return route.call(**args)
[Sun Feb 23 12:03:02 2014] [error] [client 127.0.0.1]   File "/Library/Python/2.7/site-packages/bottle.py", line 1727, in wrapper
[Sun Feb 23 12:03:02 2014] [error] [client 127.0.0.1]     rv = callback(*a, **ka)
[Sun Feb 23 12:03:02 2014] [error] [client 127.0.0.1]   File "/Users/mac/NLTK/jiebademo/jiebademo/wsgi.py", line 87, in extractFile_action
[Sun Feb 23 12:03:02 2014] [error] [client 127.0.0.1]     text = open('files/'+filename, 'rb').read()
[Sun Feb 23 12:03:02 2014] [error] [client 127.0.0.1] IOError: [Errno 2] No such file or directory: 'files/favicon.ico'
[Sun Feb 23 12:03:17 2014] [error] [client 127.0.0.1] Traceback (most recent call last):
[Sun Feb 23 12:03:17 2014] [error] [client 127.0.0.1]   File "/Library/Python/2.7/site-packages/bottle.py", line 862, in _handle
[Sun Feb 23 12:03:17 2014] [error] [client 127.0.0.1]     return route.call(**args)
[Sun Feb 23 12:03:17 2014] [error] [client 127.0.0.1]   File "/Library/Python/2.7/site-packages/bottle.py", line 1727, in wrapper
[Sun Feb 23 12:03:17 2014] [error] [client 127.0.0.1]     rv = callback(*a, **ka)
[Sun Feb 23 12:03:17 2014] [error] [client 127.0.0.1]   File "/Users/mac/NLTK/jiebademo/jiebademo/wsgi.py", line 87, in extractFile_action
[Sun Feb 23 12:03:17 2014] [error] [client 127.0.0.1]     text = open('files/'+filename, 'rb').read()
[Sun Feb 23 12:03:17 2014] [error] [client 127.0.0.1] IOError: [Errno 2] No such file or directory: 'files/favicon.ico'
[Sun Feb 23 12:03:33 2014] [error] [client 127.0.0.1] Traceback (most recent call last):
[Sun Feb 23 12:03:33 2014] [error] [client 127.0.0.1]   File "/Library/Python/2.7/site-packages/bottle.py", line 862, in _handle
[Sun Feb 23 12:03:33 2014] [error] [client 127.0.0.1]     return route.call(**args)
[Sun Feb 23 12:03:33 2014] [error] [client 127.0.0.1]   File "/Library/Python/2.7/site-packages/bottle.py", line 1727, in wrapper
[Sun Feb 23 12:03:33 2014] [error] [client 127.0.0.1]     rv = callback(*a, **ka)
[Sun Feb 23 12:03:33 2014] [error] [client 127.0.0.1]   File "/Users/mac/NLTK/jiebademo/jiebademo/wsgi.py", line 87, in extractFile_action
[Sun Feb 23 12:03:33 2014] [error] [client 127.0.0.1]     text = open('files/'+filename, 'rb').read()
[Sun Feb 23 12:03:33 2014] [error] [client 127.0.0.1] IOError: [Errno 2] No such file or directory: 'files/favicon.ico'
[Sun Feb 23 12:08:06 2014] [error] [client 127.0.0.1] Traceback (most recent call last):
[Sun Feb 23 12:08:06 2014] [error] [client 127.0.0.1]   File "/Library/Python/2.7/site-packages/bottle.py", line 862, in _handle
[Sun Feb 23 12:08:06 2014] [error] [client 127.0.0.1]     return route.call(**args)
[Sun Feb 23 12:08:06 2014] [error] [client 127.0.0.1]   File "/Library/Python/2.7/site-packages/bottle.py", line 1727, in wrapper
[Sun Feb 23 12:08:06 2014] [error] [client 127.0.0.1]     rv = callback(*a, **ka)
[Sun Feb 23 12:08:06 2014] [error] [client 127.0.0.1]   File "/Users/mac/NLTK/jiebademo/jiebademo/wsgi.py", line 87, in extractFile_action
[Sun Feb 23 12:08:06 2014] [error] [client 127.0.0.1]     text = open('files/'+filename, 'rb').read()
[Sun Feb 23 12:08:06 2014] [error] [client 127.0.0.1] IOError: [Errno 2] No such file or directory: 'files/favicon.ico'
[Sun Feb 23 12:08:06 2014] [error] [client 127.0.0.1] Traceback (most recent call last):
[Sun Feb 23 12:08:06 2014] [error] [client 127.0.0.1]   File "/Library/Python/2.7/site-packages/bottle.py", line 862, in _handle
[Sun Feb 23 12:08:06 2014] [error] [client 127.0.0.1]     return route.call(**args)
[Sun Feb 23 12:08:06 2014] [error] [client 127.0.0.1]   File "/Library/Python/2.7/site-packages/bottle.py", line 1727, in wrapper
[Sun Feb 23 12:08:06 2014] [error] [client 127.0.0.1]     rv = callback(*a, **ka)
[Sun Feb 23 12:08:06 2014] [error] [client 127.0.0.1]   File "/Users/mac/NLTK/jiebademo/jiebademo/wsgi.py", line 87, in extractFile_action
[Sun Feb 23 12:08:06 2014] [error] [client 127.0.0.1]     text = open('files/'+filename, 'rb').read()
[Sun Feb 23 12:08:06 2014] [error] [client 127.0.0.1] IOError: [Errno 2] No such file or directory: 'files/favicon.ico'
[Sun Feb 23 12:09:50 2014] [error] [client 127.0.0.1] Traceback (most recent call last):
[Sun Feb 23 12:09:50 2014] [error] [client 127.0.0.1]   File "/Library/Python/2.7/site-packages/bottle.py", line 862, in _handle
[Sun Feb 23 12:09:50 2014] [error] [client 127.0.0.1]     return route.call(**args)
[Sun Feb 23 12:09:50 2014] [error] [client 127.0.0.1]   File "/Library/Python/2.7/site-packages/bottle.py", line 1727, in wrapper
[Sun Feb 23 12:09:50 2014] [error] [client 127.0.0.1]     rv = callback(*a, **ka)
[Sun Feb 23 12:09:50 2014] [error] [client 127.0.0.1]   File "/Users/mac/NLTK/jiebademo/jiebademo/wsgi.py", line 87, in extractFile_action
[Sun Feb 23 12:09:50 2014] [error] [client 127.0.0.1]     text = open('files/'+filename, 'rb').read()
[Sun Feb 23 12:09:50 2014] [error] [client 127.0.0.1] IOError: [Errno 2] No such file or directory: 'files/favicon.ico'
[Sun Feb 23 12:19:12 2014] [error] [client 127.0.0.1] Traceback (most recent call last):
[Sun Feb 23 12:19:12 2014] [error] [client 127.0.0.1]   File "/Library/Python/2.7/site-packages/bottle.py", line 862, in _handle
[Sun Feb 23 12:19:12 2014] [error] [client 127.0.0.1]     return route.call(**args)
[Sun Feb 23 12:19:12 2014] [error] [client 127.0.0.1]   File "/Library/Python/2.7/site-packages/bottle.py", line 1727, in wrapper
[Sun Feb 23 12:19:12 2014] [error] [client 127.0.0.1]     rv = callback(*a, **ka)
[Sun Feb 23 12:19:12 2014] [error] [client 127.0.0.1]   File "/Users/mac/NLTK/jiebademo/jiebademo/wsgi.py", line 87, in extractFile_action
[Sun Feb 23 12:19:12 2014] [error] [client 127.0.0.1]     text = open('files/'+filename, 'rb').read()
[Sun Feb 23 12:19:12 2014] [error] [client 127.0.0.1] IOError: [Errno 2] No such file or directory: 'files/favicon.ico'
[Tue Feb 25 21:45:08 2014] [error] [client 127.0.0.1] mod_wsgi (pid=1622): Exception occurred processing WSGI script '/Users/mac/NLTK/jiebademo/jiebademo/adapter.wsgi'.
[Tue Feb 25 21:45:08 2014] [error] [client 127.0.0.1] IOError: failed to write data
[Thu Feb 27 14:25:12 2014] [error] [client 127.0.0.1] Traceback (most recent call last):
[Thu Feb 27 14:25:12 2014] [error] [client 127.0.0.1]   File "/Library/Python/2.7/site-packages/bottle.py", line 862, in _handle
[Thu Feb 27 14:25:12 2014] [error] [client 127.0.0.1]     return route.call(**args)
[Thu Feb 27 14:25:12 2014] [error] [client 127.0.0.1]   File "/Library/Python/2.7/site-packages/bottle.py", line 1727, in wrapper
[Thu Feb 27 14:25:12 2014] [error] [client 127.0.0.1]     rv = callback(*a, **ka)
[Thu Feb 27 14:25:12 2014] [error] [client 127.0.0.1]   File "/Users/mac/NLTK/jiebademo/jiebademo/wsgi.py", line 87, in extractFile_action
[Thu Feb 27 14:25:12 2014] [error] [client 127.0.0.1]     text = open('files/'+filename, 'rb').read()
[Thu Feb 27 14:25:12 2014] [error] [client 127.0.0.1] IOError: [Errno 2] No such file or directory: 'files/open.aspx'
[Thu Feb 27 14:26:38 2014] [error] [client 127.0.0.1] Traceback (most recent call last):
[Thu Feb 27 14:26:38 2014] [error] [client 127.0.0.1]   File "/Library/Python/2.7/site-packages/bottle.py", line 862, in _handle
[Thu Feb 27 14:26:38 2014] [error] [client 127.0.0.1]     return route.call(**args)
[Thu Feb 27 14:26:38 2014] [error] [client 127.0.0.1]   File "/Library/Python/2.7/site-packages/bottle.py", line 1727, in wrapper
[Thu Feb 27 14:26:38 2014] [error] [client 127.0.0.1]     rv = callback(*a, **ka)
[Thu Feb 27 14:26:38 2014] [error] [client 127.0.0.1]   File "/Users/mac/NLTK/jiebademo/jiebademo/wsgi.py", line 87, in extractFile_action
[Thu Feb 27 14:26:38 2014] [error] [client 127.0.0.1]     text = open('files/'+filename, 'rb').read()
[Thu Feb 27 14:26:38 2014] [error] [client 127.0.0.1] IOError: [Errno 2] No such file or directory: 'files/MFYwVKADAgEAME0wSzBJMAkGBSsOAwIaBQAEFAyBKTh0spYpEH7YNWJSZARTDeCDBBQNRFwWU0TBgn4dIKsl9AFj2L55pQIQJTke38LHhYGDrApX0sT8Wg=='
[Thu Feb 27 14:30:33 2014] [error] [client 127.0.0.1] Traceback (most recent call last):
[Thu Feb 27 14:30:33 2014] [error] [client 127.0.0.1]   File "/Library/Python/2.7/site-packages/bottle.py", line 862, in _handle
[Thu Feb 27 14:30:33 2014] [error] [client 127.0.0.1]     return route.call(**args)
[Thu Feb 27 14:30:33 2014] [error] [client 127.0.0.1]   File "/Library/Python/2.7/site-packages/bottle.py", line 1727, in wrapper
[Thu Feb 27 14:30:33 2014] [error] [client 127.0.0.1]     rv = callback(*a, **ka)
[Thu Feb 27 14:30:33 2014] [error] [client 127.0.0.1]   File "/Users/mac/NLTK/jiebademo/jiebademo/wsgi.py", line 87, in extractFile_action
[Thu Feb 27 14:30:33 2014] [error] [client 127.0.0.1]     text = open('files/'+filename, 'rb').read()
[Thu Feb 27 14:30:33 2014] [error] [client 127.0.0.1] IOError: [Errno 2] No such file or directory: 'files/favicon.ico'
[Thu Feb 27 14:32:27 2014] [error] [client 127.0.0.1] Traceback (most recent call last):, referer: http://localhost:8087/
[Thu Feb 27 14:32:27 2014] [error] [client 127.0.0.1]   File "/Library/Python/2.7/site-packages/bottle.py", line 862, in _handle, referer: http://localhost:8087/
[Thu Feb 27 14:32:27 2014] [error] [client 127.0.0.1]     return route.call(**args), referer: http://localhost:8087/
[Thu Feb 27 14:32:27 2014] [error] [client 127.0.0.1]   File "/Library/Python/2.7/site-packages/bottle.py", line 1727, in wrapper, referer: http://localhost:8087/
[Thu Feb 27 14:32:27 2014] [error] [client 127.0.0.1]     rv = callback(*a, **ka), referer: http://localhost:8087/
[Thu Feb 27 14:32:27 2014] [error] [client 127.0.0.1]   File "/Users/mac/NLTK/jiebademo/jiebademo/wsgi.py", line 87, in extractFile_action, referer: http://localhost:8087/
[Thu Feb 27 14:32:27 2014] [error] [client 127.0.0.1]     text = open('files/'+filename, 'rb').read(), referer: http://localhost:8087/
[Thu Feb 27 14:32:27 2014] [error] [client 127.0.0.1] IOError: [Errno 2] No such file or directory: 'files/h.js', referer: http://localhost:8087/
[Thu Feb 27 14:32:27 2014] [error] [client 127.0.0.1] Traceback (most recent call last):
[Thu Feb 27 14:32:27 2014] [error] [client 127.0.0.1]   File "/Library/Python/2.7/site-packages/bottle.py", line 862, in _handle
[Thu Feb 27 14:32:27 2014] [error] [client 127.0.0.1]     return route.call(**args)
[Thu Feb 27 14:32:27 2014] [error] [client 127.0.0.1]   File "/Library/Python/2.7/site-packages/bottle.py", line 1727, in wrapper
[Thu Feb 27 14:32:27 2014] [error] [client 127.0.0.1]     rv = callback(*a, **ka)
[Thu Feb 27 14:32:27 2014] [error] [client 127.0.0.1]   File "/Users/mac/NLTK/jiebademo/jiebademo/wsgi.py", line 87, in extractFile_action
[Thu Feb 27 14:32:27 2014] [error] [client 127.0.0.1]     text = open('files/'+filename, 'rb').read()
[Thu Feb 27 14:32:27 2014] [error] [client 127.0.0.1] IOError: [Errno 2] No such file or directory: 'files/favicon.ico'
[Thu Feb 27 14:32:29 2014] [error] [client 127.0.0.1] Traceback (most recent call last):, referer: http://localhost:8087/extract
[Thu Feb 27 14:32:29 2014] [error] [client 127.0.0.1]   File "/Library/Python/2.7/site-packages/bottle.py", line 862, in _handle, referer: http://localhost:8087/extract
[Thu Feb 27 14:32:29 2014] [error] [client 127.0.0.1]     return route.call(**args), referer: http://localhost:8087/extract
[Thu Feb 27 14:32:29 2014] [error] [client 127.0.0.1]   File "/Library/Python/2.7/site-packages/bottle.py", line 1727, in wrapper, referer: http://localhost:8087/extract
[Thu Feb 27 14:32:29 2014] [error] [client 127.0.0.1]     rv = callback(*a, **ka), referer: http://localhost:8087/extract
[Thu Feb 27 14:32:29 2014] [error] [client 127.0.0.1]   File "/Users/mac/NLTK/jiebademo/jiebademo/wsgi.py", line 87, in extractFile_action, referer: http://localhost:8087/extract
[Thu Feb 27 14:32:29 2014] [error] [client 127.0.0.1]     text = open('files/'+filename, 'rb').read(), referer: http://localhost:8087/extract
[Thu Feb 27 14:32:29 2014] [error] [client 127.0.0.1] IOError: [Errno 2] No such file or directory: 'files/h.js', referer: http://localhost:8087/extract
[Thu Feb 27 14:32:30 2014] [error] [client 127.0.0.1] Traceback (most recent call last):
[Thu Feb 27 14:32:30 2014] [error] [client 127.0.0.1]   File "/Library/Python/2.7/site-packages/bottle.py", line 862, in _handle
[Thu Feb 27 14:32:30 2014] [error] [client 127.0.0.1]     return route.call(**args)
[Thu Feb 27 14:32:30 2014] [error] [client 127.0.0.1]   File "/Library/Python/2.7/site-packages/bottle.py", line 1727, in wrapper
[Thu Feb 27 14:32:30 2014] [error] [client 127.0.0.1]     rv = callback(*a, **ka)
[Thu Feb 27 14:32:30 2014] [error] [client 127.0.0.1]   File "/Users/mac/NLTK/jiebademo/jiebademo/wsgi.py", line 87, in extractFile_action
[Thu Feb 27 14:32:30 2014] [error] [client 127.0.0.1]     text = open('files/'+filename, 'rb').read()
[Thu Feb 27 14:32:30 2014] [error] [client 127.0.0.1] IOError: [Errno 2] No such file or directory: 'files/favicon.ico'
[Thu Feb 27 14:40:13 2014] [error] [client 127.0.0.1] Traceback (most recent call last):
[Thu Feb 27 14:40:13 2014] [error] [client 127.0.0.1]   File "/Library/Python/2.7/site-packages/bottle.py", line 862, in _handle
[Thu Feb 27 14:40:13 2014] [error] [client 127.0.0.1]     return route.call(**args)
[Thu Feb 27 14:40:13 2014] [error] [client 127.0.0.1]   File "/Library/Python/2.7/site-packages/bottle.py", line 1727, in wrapper
[Thu Feb 27 14:40:13 2014] [error] [client 127.0.0.1]     rv = callback(*a, **ka)
[Thu Feb 27 14:40:13 2014] [error] [client 127.0.0.1]   File "/Users/mac/NLTK/jiebademo/jiebademo/wsgi.py", line 87, in extractFile_action
[Thu Feb 27 14:40:13 2014] [error] [client 127.0.0.1]     text = open('files/'+filename, 'rb').read()
[Thu Feb 27 14:40:13 2014] [error] [client 127.0.0.1] IOError: [Errno 2] No such file or directory: 'files/favicon.ico'
[Thu Feb 27 14:41:29 2014] [error] [client 127.0.0.1] Traceback (most recent call last):
[Thu Feb 27 14:41:29 2014] [error] [client 127.0.0.1]   File "/Library/Python/2.7/site-packages/bottle.py", line 862, in _handle
[Thu Feb 27 14:41:29 2014] [error] [client 127.0.0.1]     return route.call(**args)
[Thu Feb 27 14:41:29 2014] [error] [client 127.0.0.1]   File "/Library/Python/2.7/site-packages/bottle.py", line 1727, in wrapper
[Thu Feb 27 14:41:29 2014] [error] [client 127.0.0.1]     rv = callback(*a, **ka)
[Thu Feb 27 14:41:29 2014] [error] [client 127.0.0.1]   File "/Users/mac/NLTK/jiebademo/jiebademo/wsgi.py", line 87, in extractFile_action
[Thu Feb 27 14:41:29 2014] [error] [client 127.0.0.1]     text = open('files/'+filename, 'rb').read()
[Thu Feb 27 14:41:29 2014] [error] [client 127.0.0.1] IOError: [Errno 2] No such file or directory: 'files/favicon.ico'
ddd[Mon Mar 17 14:51:57 2014] [error] [client 114.90.24.54] mod_wsgi (pid=27363): Target WSGI script '/home/lanli/jiebademo/jiebademo/adapter.wsgi' cannot be loaded as Python module.
[Mon Mar 17 14:51:57 2014] [error] [client 114.90.24.54] mod_wsgi (pid=27363): Exception occurred processing WSGI script '/home/lanli/jiebademo/jiebademo/adapter.wsgi'.
[Mon Mar 17 14:51:57 2014] [error] [client 114.90.24.54] Traceback (most recent call last):
[Mon Mar 17 14:51:57 2014] [error] [client 114.90.24.54]   File "/home/lanli/jiebademo/jiebademo/adapter.wsgi", line 2, in <module>
[Mon Mar 17 14:51:57 2014] [error] [client 114.90.24.54]     import sys, os, bottle
[Mon Mar 17 14:51:57 2014] [error] [client 114.90.24.54] ImportError: No module named bottle
[Mon Mar 17 14:52:36 2014] [error] [client 114.90.24.54] mod_wsgi (pid=27426): Target WSGI script '/home/lanli/jiebademo/jiebademo/adapter.wsgi' cannot be loaded as Python module.
[Mon Mar 17 14:52:36 2014] [error] [client 114.90.24.54] mod_wsgi (pid=27426): Exception occurred processing WSGI script '/home/lanli/jiebademo/jiebademo/adapter.wsgi'.
[Mon Mar 17 14:52:36 2014] [error] [client 114.90.24.54] Traceback (most recent call last):
[Mon Mar 17 14:52:36 2014] [error] [client 114.90.24.54]   File "/home/lanli/jiebademo/jiebademo/adapter.wsgi", line 2, in <module>
[Mon Mar 17 14:52:36 2014] [error] [client 114.90.24.54]     import sys, os, bottle
[Mon Mar 17 14:52:36 2014] [error] [client 114.90.24.54] ImportError: No module named bottle
[Mon Mar 17 14:52:37 2014] [error] [client 114.90.24.54] mod_wsgi (pid=27427): Target WSGI script '/home/lanli/jiebademo/jiebademo/adapter.wsgi' cannot be loaded as Python module.
[Mon Mar 17 14:52:37 2014] [error] [client 114.90.24.54] mod_wsgi (pid=27427): Exception occurred processing WSGI script '/home/lanli/jiebademo/jiebademo/adapter.wsgi'.
[Mon Mar 17 14:52:37 2014] [error] [client 114.90.24.54] Traceback (most recent call last):
[Mon Mar 17 14:52:37 2014] [error] [client 114.90.24.54]   File "/home/lanli/jiebademo/jiebademo/adapter.wsgi", line 2, in <module>
[Mon Mar 17 14:52:37 2014] [error] [client 114.90.24.54]     import sys, os, bottle
[Mon Mar 17 14:52:37 2014] [error] [client 114.90.24.54] ImportError: No module named bottle
[Mon Mar 17 14:56:04 2014] [error] [client 114.90.24.54] mod_wsgi (pid=27427): Target WSGI script '/home/lanli/jiebademo/jiebademo/adapter.wsgi' cannot be loaded as Python module.
[Mon Mar 17 14:56:04 2014] [error] [client 114.90.24.54] mod_wsgi (pid=27427): Exception occurred processing WSGI script '/home/lanli/jiebademo/jiebademo/adapter.wsgi'.
[Mon Mar 17 14:56:04 2014] [error] [client 114.90.24.54] Traceback (most recent call last):
[Mon Mar 17 14:56:04 2014] [error] [client 114.90.24.54]   File "/home/lanli/jiebademo/jiebademo/adapter.wsgi", line 2, in <module>
[Mon Mar 17 14:56:04 2014] [error] [client 114.90.24.54]     import sys, os, bottle
[Mon Mar 17 14:56:04 2014] [error] [client 114.90.24.54] ImportError: No module named bottle
[Mon Mar 17 14:58:54 2014] [error] [client 114.90.24.54] mod_wsgi (pid=27540): Target WSGI script '/home/lanli/jiebademo/jiebademo/adapter.wsgi' cannot be loaded as Python module.
[Mon Mar 17 14:58:54 2014] [error] [client 114.90.24.54] mod_wsgi (pid=27540): Exception occurred processing WSGI script '/home/lanli/jiebademo/jiebademo/adapter.wsgi'.
[Mon Mar 17 14:58:54 2014] [error] [client 114.90.24.54] Traceback (most recent call last):
[Mon Mar 17 14:58:54 2014] [error] [client 114.90.24.54]   File "/home/lanli/jiebademo/jiebademo/adapter.wsgi", line 13, in <module>
[Mon Mar 17 14:58:54 2014] [error] [client 114.90.24.54]     import wsgi # This loads your application
[Mon Mar 17 14:58:54 2014] [error] [client 114.90.24.54]   File "/home/lanli/jiebademo/jiebademo/wsgi.py", line 98, in <module>
[Mon Mar 17 14:58:54 2014] [error] [client 114.90.24.54]     import matplotlib
[Mon Mar 17 14:58:54 2014] [error] [client 114.90.24.54] ImportError: No module named matplotlib
[Mon Mar 17 15:02:16 2014] [error] [client 114.90.24.54] mod_wsgi (pid=27540): Target WSGI script '/home/lanli/jiebademo/jiebademo/adapter.wsgi' cannot be loaded as Python module.
[Mon Mar 17 15:02:16 2014] [error] [client 114.90.24.54] mod_wsgi (pid=27540): Exception occurred processing WSGI script '/home/lanli/jiebademo/jiebademo/adapter.wsgi'.
[Mon Mar 17 15:02:16 2014] [error] [client 114.90.24.54] Traceback (most recent call last):
[Mon Mar 17 15:02:16 2014] [error] [client 114.90.24.54]   File "/home/lanli/jiebademo/jiebademo/adapter.wsgi", line 13, in <module>
[Mon Mar 17 15:02:16 2014] [error] [client 114.90.24.54]     import wsgi # This loads your application
[Mon Mar 17 15:02:16 2014] [error] [client 114.90.24.54]   File "/home/lanli/jiebademo/jiebademo/wsgi.py", line 98, in <module>
[Mon Mar 17 15:02:16 2014] [error] [client 114.90.24.54]     import matplotlib
[Mon Mar 17 15:02:16 2014] [error] [client 114.90.24.54] ImportError: No module named matplotlib
[Mon Mar 17 15:02:27 2014] [error] [client 114.90.24.54] mod_wsgi (pid=27609): Target WSGI script '/home/lanli/jiebademo/jiebademo/adapter.wsgi' cannot be loaded as Python module.
[Mon Mar 17 15:02:27 2014] [error] [client 114.90.24.54] mod_wsgi (pid=27609): Exception occurred processing WSGI script '/home/lanli/jiebademo/jiebademo/adapter.wsgi'.
[Mon Mar 17 15:02:27 2014] [error] [client 114.90.24.54] Traceback (most recent call last):
[Mon Mar 17 15:02:27 2014] [error] [client 114.90.24.54]   File "/home/lanli/jiebademo/jiebademo/adapter.wsgi", line 13, in <module>
[Mon Mar 17 15:02:27 2014] [error] [client 114.90.24.54]     import wsgi # This loads your application
[Mon Mar 17 15:02:27 2014] [error] [client 114.90.24.54]   File "/home/lanli/jiebademo/jiebademo/wsgi.py", line 98, in <module>
[Mon Mar 17 15:02:27 2014] [error] [client 114.90.24.54]     import matplotlib
[Mon Mar 17 15:02:27 2014] [error] [client 114.90.24.54] ImportError: No module named matplotlib
[Mon Mar 17 15:06:15 2014] [error] [client 114.90.24.54] mod_wsgi (pid=27666): Target WSGI script '/home/lanli/jiebademo/jiebademo/adapter.wsgi' cannot be loaded as Python module.
[Mon Mar 17 15:06:15 2014] [error] [client 114.90.24.54] mod_wsgi (pid=27666): Exception occurred processing WSGI script '/home/lanli/jiebademo/jiebademo/adapter.wsgi'.
[Mon Mar 17 15:06:15 2014] [error] [client 114.90.24.54] Traceback (most recent call last):
[Mon Mar 17 15:06:15 2014] [error] [client 114.90.24.54]   File "/home/lanli/jiebademo/jiebademo/adapter.wsgi", line 13, in <module>
[Mon Mar 17 15:06:15 2014] [error] [client 114.90.24.54]     import wsgi # This loads your application
[Mon Mar 17 15:06:15 2014] [error] [client 114.90.24.54]   File "/home/lanli/jiebademo/jiebademo/wsgi.py", line 98, in <module>
[Mon Mar 17 15:06:15 2014] [error] [client 114.90.24.54]     import matplotlib
[Mon Mar 17 15:06:15 2014] [error] [client 114.90.24.54] ImportError: No module named matplotlib
[Mon Mar 17 15:08:32 2014] [error] [client 114.90.24.54] mod_wsgi (pid=30519): Target WSGI script '/home/lanli/jiebademo/jiebademo/adapter.wsgi' cannot be loaded as Python module.
[Mon Mar 17 15:08:32 2014] [error] [client 114.90.24.54] mod_wsgi (pid=30519): Exception occurred processing WSGI script '/home/lanli/jiebademo/jiebademo/adapter.wsgi'.
[Mon Mar 17 15:08:32 2014] [error] [client 114.90.24.54] Traceback (most recent call last):
[Mon Mar 17 15:08:32 2014] [error] [client 114.90.24.54]   File "/home/lanli/jiebademo/jiebademo/adapter.wsgi", line 13, in <module>
[Mon Mar 17 15:08:32 2014] [error] [client 114.90.24.54]     import wsgi # This loads your application
[Mon Mar 17 15:08:32 2014] [error] [client 114.90.24.54]   File "/home/lanli/jiebademo/jiebademo/wsgi.py", line 98, in <module>
[Mon Mar 17 15:08:32 2014] [error] [client 114.90.24.54]     import matplotlib
[Mon Mar 17 15:08:32 2014] [error] [client 114.90.24.54]   File "/usr/lib/pymodules/python2.7/matplotlib/__init__.py", line 774, in <module>
[Mon Mar 17 15:08:32 2014] [error] [client 114.90.24.54]     rcParams = rc_params()
[Mon Mar 17 15:08:32 2014] [error] [client 114.90.24.54]   File "/usr/lib/pymodules/python2.7/matplotlib/__init__.py", line 692, in rc_params
[Mon Mar 17 15:08:32 2014] [error] [client 114.90.24.54]     fname = matplotlib_fname()
[Mon Mar 17 15:08:32 2014] [error] [client 114.90.24.54]   File "/usr/lib/pymodules/python2.7/matplotlib/__init__.py", line 604, in matplotlib_fname
[Mon Mar 17 15:08:32 2014] [error] [client 114.90.24.54]     fname = os.path.join(get_configdir(), 'matplotlibrc')
[Mon Mar 17 15:08:32 2014] [error] [client 114.90.24.54]   File "/usr/lib/pymodules/python2.7/matplotlib/__init__.py", line 253, in wrapper
[Mon Mar 17 15:08:32 2014] [error] [client 114.90.24.54]     ret = func(*args, **kwargs)
[Mon Mar 17 15:08:32 2014] [error] [client 114.90.24.54]   File "/usr/lib/pymodules/python2.7/matplotlib/__init__.py", line 478, in _get_configdir
[Mon Mar 17 15:08:32 2014] [error] [client 114.90.24.54]     raise RuntimeError("Failed to create %s/.matplotlib; consider setting MPLCONFIGDIR to a writable directory for matplotlib configuration data"%h)
[Mon Mar 17 15:08:32 2014] [error] [client 114.90.24.54] RuntimeError: Failed to create /var/www/.matplotlib; consider setting MPLCONFIGDIR to a writable directory for matplotlib configuration data
[Mon Mar 17 17:51:15 2014] [error] [client 124.78.111.43] mod_wsgi (pid=32301): Exception occurred processing WSGI script '/home/lanli/jiebademo/jiebademo/adapter.wsgi'.
[Mon Mar 17 17:51:15 2014] [error] [client 124.78.111.43] IOError: failed to write data
[Mon Mar 17 18:20:24 2014] [error] [client 124.78.111.43] Traceback (most recent call last):, referer: http://42.121.109.6:8088/
[Mon Mar 17 18:20:24 2014] [error] [client 124.78.111.43]   File "/usr/lib/python2.7/dist-packages/bottle.py", line 737, in _handle, referer: http://42.121.109.6:8088/
[Mon Mar 17 18:20:24 2014] [error] [client 124.78.111.43]     return route.call(**args), referer: http://42.121.109.6:8088/
[Mon Mar 17 18:20:24 2014] [error] [client 124.78.111.43]   File "/usr/lib/python2.7/dist-packages/bottle.py", line 1454, in wrapper, referer: http://42.121.109.6:8088/
[Mon Mar 17 18:20:24 2014] [error] [client 124.78.111.43]     rv = callback(*a, **ka), referer: http://42.121.109.6:8088/
[Mon Mar 17 18:20:24 2014] [error] [client 124.78.111.43]   File "/home/lanli/jiebademo/jiebademo/wsgi.py", line 176, in extractSubmit_action, referer: http://42.121.109.6:8088/
[Mon Mar 17 18:20:24 2014] [error] [client 124.78.111.43]     open(path + '/files/' + fn, 'wb').write(text), referer: http://42.121.109.6:8088/
[Mon Mar 17 18:20:24 2014] [error] [client 124.78.111.43] IOError: [Errno 13] Permission denied: '/home/lanli/jiebademo/jiebademo/files/zengguofang2.txt', referer: http://42.121.109.6:8088/
[Mon Mar 17 18:27:23 2014] [error] [client 124.78.111.43] Traceback (most recent call last):, referer: http://42.121.109.6:8088/extract
[Mon Mar 17 18:27:23 2014] [error] [client 124.78.111.43]   File "/usr/lib/python2.7/dist-packages/bottle.py", line 737, in _handle, referer: http://42.121.109.6:8088/extract
[Mon Mar 17 18:27:23 2014] [error] [client 124.78.111.43]     return route.call(**args), referer: http://42.121.109.6:8088/extract
[Mon Mar 17 18:27:23 2014] [error] [client 124.78.111.43]   File "/usr/lib/python2.7/dist-packages/bottle.py", line 1454, in wrapper, referer: http://42.121.109.6:8088/extract
[Mon Mar 17 18:27:23 2014] [error] [client 124.78.111.43]     rv = callback(*a, **ka), referer: http://42.121.109.6:8088/extract
[Mon Mar 17 18:27:23 2014] [error] [client 124.78.111.43]   File "/home/lanli/jiebademo/jiebademo/wsgi.py", line 182, in extractSubmit_action, referer: http://42.121.109.6:8088/extract
[Mon Mar 17 18:27:23 2014] [error] [client 124.78.111.43]     sqlitedb.addText(name,author,period,fn,uploader), referer: http://42.121.109.6:8088/extract
[Mon Mar 17 18:27:23 2014] [error] [client 124.78.111.43]   File "/home/lanli/jiebademo/jiebademo/sqlitedb.py", line 16, in addText, referer: http://42.121.109.6:8088/extract
[Mon Mar 17 18:27:23 2014] [error] [client 124.78.111.43]     VALUES (?,?,?,?,?,datetime('now'))''',(name,author,period,path,uploader)), referer: http://42.121.109.6:8088/extract
[Mon Mar 17 18:27:23 2014] [error] [client 124.78.111.43] OperationalError: attempt to write a readonly database, referer: http://42.121.109.6:8088/extract
[Mon Mar 17 18:31:54 2014] [error] [client 124.78.111.43] Traceback (most recent call last):, referer: http://42.121.109.6:8088/extract
[Mon Mar 17 18:31:54 2014] [error] [client 124.78.111.43]   File "/usr/lib/python2.7/dist-packages/bottle.py", line 737, in _handle, referer: http://42.121.109.6:8088/extract
[Mon Mar 17 18:31:54 2014] [error] [client 124.78.111.43]     return route.call(**args), referer: http://42.121.109.6:8088/extract
[Mon Mar 17 18:31:54 2014] [error] [client 124.78.111.43]   File "/usr/lib/python2.7/dist-packages/bottle.py", line 1454, in wrapper, referer: http://42.121.109.6:8088/extract
[Mon Mar 17 18:31:54 2014] [error] [client 124.78.111.43]     rv = callback(*a, **ka), referer: http://42.121.109.6:8088/extract
[Mon Mar 17 18:31:54 2014] [error] [client 124.78.111.43]   File "/home/lanli/jiebademo/jiebademo/wsgi.py", line 182, in extractSubmit_action, referer: http://42.121.109.6:8088/extract
[Mon Mar 17 18:31:54 2014] [error] [client 124.78.111.43]     sqlitedb.addText(name,author,period,fn,uploader), referer: http://42.121.109.6:8088/extract
[Mon Mar 17 18:31:54 2014] [error] [client 124.78.111.43]   File "/home/lanli/jiebademo/jiebademo/sqlitedb.py", line 16, in addText, referer: http://42.121.109.6:8088/extract
[Mon Mar 17 18:31:54 2014] [error] [client 124.78.111.43]     VALUES (?,?,?,?,?,datetime('now'))''',(name,author,period,path,uploader)), referer: http://42.121.109.6:8088/extract
[Mon Mar 17 18:31:54 2014] [error] [client 124.78.111.43] OperationalError: unable to open database file, referer: http://42.121.109.6:8088/extract
[Mon Mar 17 18:32:15 2014] [error] [client 124.78.111.43] Traceback (most recent call last):, referer: http://42.121.109.6:8088/extract
[Mon Mar 17 18:32:15 2014] [error] [client 124.78.111.43]   File "/usr/lib/python2.7/dist-packages/bottle.py", line 737, in _handle, referer: http://42.121.109.6:8088/extract
[Mon Mar 17 18:32:15 2014] [error] [client 124.78.111.43]     return route.call(**args), referer: http://42.121.109.6:8088/extract
[Mon Mar 17 18:32:15 2014] [error] [client 124.78.111.43]   File "/usr/lib/python2.7/dist-packages/bottle.py", line 1454, in wrapper, referer: http://42.121.109.6:8088/extract
[Mon Mar 17 18:32:15 2014] [error] [client 124.78.111.43]     rv = callback(*a, **ka), referer: http://42.121.109.6:8088/extract
[Mon Mar 17 18:32:15 2014] [error] [client 124.78.111.43]   File "/home/lanli/jiebademo/jiebademo/wsgi.py", line 182, in extractSubmit_action, referer: http://42.121.109.6:8088/extract
[Mon Mar 17 18:32:15 2014] [error] [client 124.78.111.43]     sqlitedb.addText(name,author,period,fn,uploader), referer: http://42.121.109.6:8088/extract
[Mon Mar 17 18:32:15 2014] [error] [client 124.78.111.43]   File "/home/lanli/jiebademo/jiebademo/sqlitedb.py", line 16, in addText, referer: http://42.121.109.6:8088/extract
[Mon Mar 17 18:32:15 2014] [error] [client 124.78.111.43]     VALUES (?,?,?,?,?,datetime('now'))''',(name,author,period,path,uploader)), referer: http://42.121.109.6:8088/extract
[Mon Mar 17 18:32:15 2014] [error] [client 124.78.111.43] OperationalError: unable to open database file, referer: http://42.121.109.6:8088/extract
[Mon Mar 17 18:33:48 2014] [error] [client 124.78.111.43] Traceback (most recent call last):, referer: http://42.121.109.6:8088/extract
[Mon Mar 17 18:33:48 2014] [error] [client 124.78.111.43]   File "/usr/lib/python2.7/dist-packages/bottle.py", line 737, in _handle, referer: http://42.121.109.6:8088/extract
[Mon Mar 17 18:33:48 2014] [error] [client 124.78.111.43]     return route.call(**args), referer: http://42.121.109.6:8088/extract
[Mon Mar 17 18:33:48 2014] [error] [client 124.78.111.43]   File "/usr/lib/python2.7/dist-packages/bottle.py", line 1454, in wrapper, referer: http://42.121.109.6:8088/extract
[Mon Mar 17 18:33:48 2014] [error] [client 124.78.111.43]     rv = callback(*a, **ka), referer: http://42.121.109.6:8088/extract
[Mon Mar 17 18:33:48 2014] [error] [client 124.78.111.43]   File "/home/lanli/jiebademo/jiebademo/wsgi.py", line 182, in extractSubmit_action, referer: http://42.121.109.6:8088/extract
[Mon Mar 17 18:33:48 2014] [error] [client 124.78.111.43]     sqlitedb.addText(name,author,period,fn,uploader), referer: http://42.121.109.6:8088/extract
[Mon Mar 17 18:33:48 2014] [error] [client 124.78.111.43]   File "/home/lanli/jiebademo/jiebademo/sqlitedb.py", line 16, in addText, referer: http://42.121.109.6:8088/extract
[Mon Mar 17 18:33:48 2014] [error] [client 124.78.111.43]     VALUES (?,?,?,?,?,datetime('now'))''',(name,author,period,path,uploader)), referer: http://42.121.109.6:8088/extract
[Mon Mar 17 18:33:48 2014] [error] [client 124.78.111.43] OperationalError: unable to open database file, referer: http://42.121.109.6:8088/extract
[Mon Mar 17 18:34:15 2014] [error] [client 124.78.111.43] Traceback (most recent call last):, referer: http://42.121.109.6:8088/extract
[Mon Mar 17 18:34:15 2014] [error] [client 124.78.111.43]   File "/usr/lib/python2.7/dist-packages/bottle.py", line 737, in _handle, referer: http://42.121.109.6:8088/extract
[Mon Mar 17 18:34:15 2014] [error] [client 124.78.111.43]     return route.call(**args), referer: http://42.121.109.6:8088/extract
[Mon Mar 17 18:34:15 2014] [error] [client 124.78.111.43]   File "/usr/lib/python2.7/dist-packages/bottle.py", line 1454, in wrapper, referer: http://42.121.109.6:8088/extract
[Mon Mar 17 18:34:15 2014] [error] [client 124.78.111.43]     rv = callback(*a, **ka), referer: http://42.121.109.6:8088/extract
[Mon Mar 17 18:34:15 2014] [error] [client 124.78.111.43]   File "/home/lanli/jiebademo/jiebademo/wsgi.py", line 182, in extractSubmit_action, referer: http://42.121.109.6:8088/extract
[Mon Mar 17 18:34:15 2014] [error] [client 124.78.111.43]     sqlitedb.addText(name,author,period,fn,uploader), referer: http://42.121.109.6:8088/extract
[Mon Mar 17 18:34:15 2014] [error] [client 124.78.111.43]   File "/home/lanli/jiebademo/jiebademo/sqlitedb.py", line 16, in addText, referer: http://42.121.109.6:8088/extract
[Mon Mar 17 18:34:15 2014] [error] [client 124.78.111.43]     VALUES (?,?,?,?,?,datetime('now'))''',(name,author,period,path,uploader)), referer: http://42.121.109.6:8088/extract
[Mon Mar 17 18:34:15 2014] [error] [client 124.78.111.43] OperationalError: unable to open database file, referer: http://42.121.109.6:8088/extract
[Mon Mar 17 19:17:09 2014] [error] [client 58.34.169.13] Traceback (most recent call last):
[Mon Mar 17 19:17:09 2014] [error] [client 58.34.169.13]   File "/usr/lib/python2.7/dist-packages/bottle.py", line 737, in _handle
[Mon Mar 17 19:17:09 2014] [error] [client 58.34.169.13]     return route.call(**args)
[Mon Mar 17 19:17:09 2014] [error] [client 58.34.169.13]   File "/usr/lib/python2.7/dist-packages/bottle.py", line 1454, in wrapper
[Mon Mar 17 19:17:09 2014] [error] [client 58.34.169.13]     rv = callback(*a, **ka)
[Mon Mar 17 19:17:09 2014] [error] [client 58.34.169.13]   File "/home/lanli/jiebademo/jiebademo/wsgi.py", line 108, in extractFile_action
[Mon Mar 17 19:17:09 2014] [error] [client 58.34.169.13]     text = open(path + 'files/'+filename, 'rb').read()
[Mon Mar 17 19:17:09 2014] [error] [client 58.34.169.13] IOError: [Errno 2] No such file or directory: '/home/lanli/jiebademo/jiebademofiles/wangyangming.txt'
[Mon Mar 17 19:17:16 2014] [error] [client 58.34.169.13] Traceback (most recent call last):, referer: http://42.121.109.6:8088/
[Mon Mar 17 19:17:16 2014] [error] [client 58.34.169.13]   File "/usr/lib/python2.7/dist-packages/bottle.py", line 737, in _handle, referer: http://42.121.109.6:8088/
[Mon Mar 17 19:17:16 2014] [error] [client 58.34.169.13]     return route.call(**args), referer: http://42.121.109.6:8088/
[Mon Mar 17 19:17:16 2014] [error] [client 58.34.169.13]   File "/usr/lib/python2.7/dist-packages/bottle.py", line 1454, in wrapper, referer: http://42.121.109.6:8088/
[Mon Mar 17 19:17:16 2014] [error] [client 58.34.169.13]     rv = callback(*a, **ka), referer: http://42.121.109.6:8088/
[Mon Mar 17 19:17:16 2014] [error] [client 58.34.169.13]   File "/home/lanli/jiebademo/jiebademo/wsgi.py", line 108, in extractFile_action, referer: http://42.121.109.6:8088/
[Mon Mar 17 19:17:16 2014] [error] [client 58.34.169.13]     text = open(path + 'files/'+filename, 'rb').read(), referer: http://42.121.109.6:8088/
[Mon Mar 17 19:17:16 2014] [error] [client 58.34.169.13] IOError: [Errno 2] No such file or directory: '/home/lanli/jiebademo/jiebademofiles/zengguofang.txt', referer: http://42.121.109.6:8088/
[Mon Mar 17 19:17:20 2014] [error] [client 58.34.169.13] Traceback (most recent call last):, referer: http://42.121.109.6:8088/
[Mon Mar 17 19:17:20 2014] [error] [client 58.34.169.13]   File "/usr/lib/python2.7/dist-packages/bottle.py", line 737, in _handle, referer: http://42.121.109.6:8088/
[Mon Mar 17 19:17:20 2014] [error] [client 58.34.169.13]     return route.call(**args), referer: http://42.121.109.6:8088/
[Mon Mar 17 19:17:20 2014] [error] [client 58.34.169.13]   File "/usr/lib/python2.7/dist-packages/bottle.py", line 1454, in wrapper, referer: http://42.121.109.6:8088/
[Mon Mar 17 19:17:20 2014] [error] [client 58.34.169.13]     rv = callback(*a, **ka), referer: http://42.121.109.6:8088/
[Mon Mar 17 19:17:20 2014] [error] [client 58.34.169.13]   File "/home/lanli/jiebademo/jiebademo/wsgi.py", line 108, in extractFile_action, referer: http://42.121.109.6:8088/
[Mon Mar 17 19:17:20 2014] [error] [client 58.34.169.13]     text = open(path + 'files/'+filename, 'rb').read(), referer: http://42.121.109.6:8088/
[Mon Mar 17 19:17:20 2014] [error] [client 58.34.169.13] IOError: [Errno 2] No such file or directory: '/home/lanli/jiebademo/jiebademofiles/wangyangming.txt', referer: http://42.121.109.6:8088/
[Mon Mar 17 20:29:24 2014] [error] [client 58.34.169.13] Traceback (most recent call last):, referer: http://42.121.109.6:8088/
[Mon Mar 17 20:29:24 2014] [error] [client 58.34.169.13]   File "/usr/lib/python2.7/dist-packages/bottle.py", line 737, in _handle, referer: http://42.121.109.6:8088/
[Mon Mar 17 20:29:24 2014] [error] [client 58.34.169.13]     return route.call(**args), referer: http://42.121.109.6:8088/
[Mon Mar 17 20:29:24 2014] [error] [client 58.34.169.13]   File "/usr/lib/python2.7/dist-packages/bottle.py", line 1454, in wrapper, referer: http://42.121.109.6:8088/
[Mon Mar 17 20:29:24 2014] [error] [client 58.34.169.13]     rv = callback(*a, **ka), referer: http://42.121.109.6:8088/
[Mon Mar 17 20:29:24 2014] [error] [client 58.34.169.13]   File "/home/lanli/jiebademo/jiebademo/wsgi.py", line 154, in extractFile_action, referer: http://42.121.109.6:8088/
[Mon Mar 17 20:29:24 2014] [error] [client 58.34.169.13]     return template("extract_form",content=text,tags=keyCounts,topk=topk,keyImgUrl='', texts=sqlitedb.getTexts(), selectedFile=filename), referer: http://42.121.109.6:8088/
[Mon Mar 17 20:29:24 2014] [error] [client 58.34.169.13] NameError: global name 'keyCounts' is not defined, referer: http://42.121.109.6:8088/
[Mon Mar 17 20:42:46 2014] [error] [client 58.34.169.13] mod_wsgi (pid=5024): Target WSGI script '/home/lanli/jiebademo/jiebademo/adapter.wsgi' cannot be loaded as Python module.
[Mon Mar 17 20:42:46 2014] [error] [client 58.34.169.13] mod_wsgi (pid=5024): Exception occurred processing WSGI script '/home/lanli/jiebademo/jiebademo/adapter.wsgi'.
[Mon Mar 17 20:42:46 2014] [error] [client 58.34.169.13] Traceback (most recent call last):
[Mon Mar 17 20:42:46 2014] [error] [client 58.34.169.13]   File "/home/lanli/jiebademo/jiebademo/adapter.wsgi", line 13, in <module>
[Mon Mar 17 20:42:46 2014] [error] [client 58.34.169.13]     import wsgi # This loads your application
[Mon Mar 17 20:42:46 2014] [error] [client 58.34.169.13]   File "/home/lanli/jiebademo/jiebademo/wsgi.py", line 1, in <module>
[Mon Mar 17 20:42:46 2014] [error] [client 58.34.169.13]     usr/bin/python
[Mon Mar 17 20:42:46 2014] [error] [client 58.34.169.13] NameError: name 'usr' is not defined
[Mon Mar 17 20:42:50 2014] [error] [client 58.34.169.13] mod_wsgi (pid=5023): Target WSGI script '/home/lanli/jiebademo/jiebademo/adapter.wsgi' cannot be loaded as Python module.
[Mon Mar 17 20:42:50 2014] [error] [client 58.34.169.13] mod_wsgi (pid=5023): Exception occurred processing WSGI script '/home/lanli/jiebademo/jiebademo/adapter.wsgi'.
[Mon Mar 17 20:42:50 2014] [error] [client 58.34.169.13] Traceback (most recent call last):
[Mon Mar 17 20:42:50 2014] [error] [client 58.34.169.13]   File "/home/lanli/jiebademo/jiebademo/adapter.wsgi", line 13, in <module>
[Mon Mar 17 20:42:50 2014] [error] [client 58.34.169.13]     import wsgi # This loads your application
[Mon Mar 17 20:42:50 2014] [error] [client 58.34.169.13]   File "/home/lanli/jiebademo/jiebademo/wsgi.py", line 1, in <module>
[Mon Mar 17 20:42:50 2014] [error] [client 58.34.169.13]     usr/bin/python
[Mon Mar 17 20:42:50 2014] [error] [client 58.34.169.13] NameError: name 'usr' is not defined
[Mon Mar 17 20:42:50 2014] [error] [client 58.34.169.13] mod_wsgi (pid=5024): Target WSGI script '/home/lanli/jiebademo/jiebademo/adapter.wsgi' cannot be loaded as Python module.
[Mon Mar 17 20:42:50 2014] [error] [client 58.34.169.13] mod_wsgi (pid=5024): Exception occurred processing WSGI script '/home/lanli/jiebademo/jiebademo/adapter.wsgi'.
[Mon Mar 17 20:42:50 2014] [error] [client 58.34.169.13] Traceback (most recent call last):
[Mon Mar 17 20:42:50 2014] [error] [client 58.34.169.13]   File "/home/lanli/jiebademo/jiebademo/adapter.wsgi", line 13, in <module>
[Mon Mar 17 20:42:50 2014] [error] [client 58.34.169.13]     import wsgi # This loads your application
[Mon Mar 17 20:42:50 2014] [error] [client 58.34.169.13]   File "/home/lanli/jiebademo/jiebademo/wsgi.py", line 1, in <module>
[Mon Mar 17 20:42:50 2014] [error] [client 58.34.169.13]     usr/bin/python
[Mon Mar 17 20:42:50 2014] [error] [client 58.34.169.13] NameError: name 'usr' is not defined
[Mon Mar 17 20:42:53 2014] [error] [client 58.34.169.13] mod_wsgi (pid=5023): Target WSGI script '/home/lanli/jiebademo/jiebademo/adapter.wsgi' cannot be loaded as Python module.
[Mon Mar 17 20:42:53 2014] [error] [client 58.34.169.13] mod_wsgi (pid=5023): Exception occurred processing WSGI script '/home/lanli/jiebademo/jiebademo/adapter.wsgi'.
[Mon Mar 17 20:42:53 2014] [error] [client 58.34.169.13] Traceback (most recent call last):
[Mon Mar 17 20:42:53 2014] [error] [client 58.34.169.13]   File "/home/lanli/jiebademo/jiebademo/adapter.wsgi", line 13, in <module>
[Mon Mar 17 20:42:53 2014] [error] [client 58.34.169.13]     import wsgi # This loads your application
[Mon Mar 17 20:42:53 2014] [error] [client 58.34.169.13]   File "/home/lanli/jiebademo/jiebademo/wsgi.py", line 1, in <module>
[Mon Mar 17 20:42:53 2014] [error] [client 58.34.169.13]     usr/bin/python
[Mon Mar 17 20:42:53 2014] [error] [client 58.34.169.13] NameError: name 'usr' is not defined
[Mon Mar 17 20:42:53 2014] [error] [client 58.34.169.13] mod_wsgi (pid=5024): Target WSGI script '/home/lanli/jiebademo/jiebademo/adapter.wsgi' cannot be loaded as Python module.
[Mon Mar 17 20:42:53 2014] [error] [client 58.34.169.13] mod_wsgi (pid=5024): Exception occurred processing WSGI script '/home/lanli/jiebademo/jiebademo/adapter.wsgi'.
[Mon Mar 17 20:42:53 2014] [error] [client 58.34.169.13] Traceback (most recent call last):
[Mon Mar 17 20:42:53 2014] [error] [client 58.34.169.13]   File "/home/lanli/jiebademo/jiebademo/adapter.wsgi", line 13, in <module>
[Mon Mar 17 20:42:53 2014] [error] [client 58.34.169.13]     import wsgi # This loads your application
[Mon Mar 17 20:42:53 2014] [error] [client 58.34.169.13]   File "/home/lanli/jiebademo/jiebademo/wsgi.py", line 1, in <module>
[Mon Mar 17 20:42:53 2014] [error] [client 58.34.169.13]     usr/bin/python
[Mon Mar 17 20:42:53 2014] [error] [client 58.34.169.13] NameError: name 'usr' is not defined
[Mon Mar 17 20:43:36 2014] [error] [client 58.34.169.13] mod_wsgi (pid=5086): Target WSGI script '/home/lanli/jiebademo/jiebademo/adapter.wsgi' cannot be loaded as Python module.
[Mon Mar 17 20:43:36 2014] [error] [client 58.34.169.13] mod_wsgi (pid=5086): Exception occurred processing WSGI script '/home/lanli/jiebademo/jiebademo/adapter.wsgi'.
[Mon Mar 17 20:43:36 2014] [error] [client 58.34.169.13] Traceback (most recent call last):
[Mon Mar 17 20:43:36 2014] [error] [client 58.34.169.13]   File "/home/lanli/jiebademo/jiebademo/adapter.wsgi", line 13, in <module>
[Mon Mar 17 20:43:36 2014] [error] [client 58.34.169.13]     import wsgi # This loads your application
[Mon Mar 17 20:43:36 2014] [error] [client 58.34.169.13]   File "/home/lanli/jiebademo/jiebademo/wsgi.py", line 1, in <module>
[Mon Mar 17 20:43:36 2014] [error] [client 58.34.169.13]     usr/bin/python
[Mon Mar 17 20:43:36 2014] [error] [client 58.34.169.13] NameError: name 'usr' is not defined
[Mon Mar 17 20:43:36 2014] [error] [client 58.34.169.13] mod_wsgi (pid=5087): Target WSGI script '/home/lanli/jiebademo/jiebademo/adapter.wsgi' cannot be loaded as Python module.
[Mon Mar 17 20:43:36 2014] [error] [client 58.34.169.13] mod_wsgi (pid=5087): Exception occurred processing WSGI script '/home/lanli/jiebademo/jiebademo/adapter.wsgi'.
[Mon Mar 17 20:43:36 2014] [error] [client 58.34.169.13] Traceback (most recent call last):
[Mon Mar 17 20:43:36 2014] [error] [client 58.34.169.13]   File "/home/lanli/jiebademo/jiebademo/adapter.wsgi", line 13, in <module>
[Mon Mar 17 20:43:36 2014] [error] [client 58.34.169.13]     import wsgi # This loads your application
[Mon Mar 17 20:43:36 2014] [error] [client 58.34.169.13]   File "/home/lanli/jiebademo/jiebademo/wsgi.py", line 1, in <module>
[Mon Mar 17 20:43:36 2014] [error] [client 58.34.169.13]     usr/bin/python
[Mon Mar 17 20:43:36 2014] [error] [client 58.34.169.13] NameError: name 'usr' is not defined
[Mon Mar 17 20:43:40 2014] [error] [client 58.34.169.13] mod_wsgi (pid=5086): Target WSGI script '/home/lanli/jiebademo/jiebademo/adapter.wsgi' cannot be loaded as Python module.
[Mon Mar 17 20:43:40 2014] [error] [client 58.34.169.13] mod_wsgi (pid=5086): Exception occurred processing WSGI script '/home/lanli/jiebademo/jiebademo/adapter.wsgi'.
[Mon Mar 17 20:43:40 2014] [error] [client 58.34.169.13] Traceback (most recent call last):
[Mon Mar 17 20:43:40 2014] [error] [client 58.34.169.13]   File "/home/lanli/jiebademo/jiebademo/adapter.wsgi", line 13, in <module>
[Mon Mar 17 20:43:40 2014] [error] [client 58.34.169.13]     import wsgi # This loads your application
[Mon Mar 17 20:43:40 2014] [error] [client 58.34.169.13]   File "/home/lanli/jiebademo/jiebademo/wsgi.py", line 1, in <module>
[Mon Mar 17 20:43:40 2014] [error] [client 58.34.169.13]     usr/bin/python
[Mon Mar 17 20:43:40 2014] [error] [client 58.34.169.13] NameError: name 'usr' is not defined
[Mon Mar 17 20:43:40 2014] [error] [client 58.34.169.13] mod_wsgi (pid=5087): Target WSGI script '/home/lanli/jiebademo/jiebademo/adapter.wsgi' cannot be loaded as Python module.
[Mon Mar 17 20:43:40 2014] [error] [client 58.34.169.13] mod_wsgi (pid=5087): Exception occurred processing WSGI script '/home/lanli/jiebademo/jiebademo/adapter.wsgi'.
[Mon Mar 17 20:43:40 2014] [error] [client 58.34.169.13] Traceback (most recent call last):
[Mon Mar 17 20:43:40 2014] [error] [client 58.34.169.13]   File "/home/lanli/jiebademo/jiebademo/adapter.wsgi", line 13, in <module>
[Mon Mar 17 20:43:40 2014] [error] [client 58.34.169.13]     import wsgi # This loads your application
[Mon Mar 17 20:43:40 2014] [error] [client 58.34.169.13]   File "/home/lanli/jiebademo/jiebademo/wsgi.py", line 1, in <module>
[Mon Mar 17 20:43:40 2014] [error] [client 58.34.169.13]     usr/bin/python
[Mon Mar 17 20:43:40 2014] [error] [client 58.34.169.13] NameError: name 'usr' is not defined
[Mon Mar 17 20:45:32 2014] [error] [client 58.34.169.13] mod_wsgi (pid=5153): Target WSGI script '/home/lanli/jiebademo/jiebademo/adapter.wsgi' cannot be loaded as Python module.
[Mon Mar 17 20:45:32 2014] [error] [client 58.34.169.13] mod_wsgi (pid=5153): Exception occurred processing WSGI script '/home/lanli/jiebademo/jiebademo/adapter.wsgi'.
[Mon Mar 17 20:45:32 2014] [error] [client 58.34.169.13] Traceback (most recent call last):
[Mon Mar 17 20:45:32 2014] [error] [client 58.34.169.13]   File "/home/lanli/jiebademo/jiebademo/adapter.wsgi", line 13, in <module>
[Mon Mar 17 20:45:32 2014] [error] [client 58.34.169.13]     import wsgi # This loads your application
[Mon Mar 17 20:45:32 2014] [error] [client 58.34.169.13]   File "/home/lanli/jiebademo/jiebademo/wsgi.py", line 1, in <module>
[Mon Mar 17 20:45:32 2014] [error] [client 58.34.169.13]     usr/bin/python
[Mon Mar 17 20:45:32 2014] [error] [client 58.34.169.13] NameError: name 'usr' is not defined
[Mon Mar 17 20:45:32 2014] [error] [client 58.34.169.13] mod_wsgi (pid=5154): Target WSGI script '/home/lanli/jiebademo/jiebademo/adapter.wsgi' cannot be loaded as Python module.
[Mon Mar 17 20:45:32 2014] [error] [client 58.34.169.13] mod_wsgi (pid=5154): Exception occurred processing WSGI script '/home/lanli/jiebademo/jiebademo/adapter.wsgi'.
[Mon Mar 17 20:45:32 2014] [error] [client 58.34.169.13] Traceback (most recent call last):
[Mon Mar 17 20:45:32 2014] [error] [client 58.34.169.13]   File "/home/lanli/jiebademo/jiebademo/adapter.wsgi", line 13, in <module>
[Mon Mar 17 20:45:32 2014] [error] [client 58.34.169.13]     import wsgi # This loads your application
[Mon Mar 17 20:45:32 2014] [error] [client 58.34.169.13]   File "/home/lanli/jiebademo/jiebademo/wsgi.py", line 1, in <module>
[Mon Mar 17 20:45:32 2014] [error] [client 58.34.169.13]     usr/bin/python
[Mon Mar 17 20:45:32 2014] [error] [client 58.34.169.13] NameError: name 'usr' is not defined
[Mon Mar 17 20:47:18 2014] [error] [client 58.34.169.13] mod_wsgi (pid=5216): Target WSGI script '/home/lanli/jiebademo/jiebademo/adapter.wsgi' cannot be loaded as Python module.
[Mon Mar 17 20:47:18 2014] [error] [client 58.34.169.13] mod_wsgi (pid=5216): Exception occurred processing WSGI script '/home/lanli/jiebademo/jiebademo/adapter.wsgi'.
[Mon Mar 17 20:47:18 2014] [error] [client 58.34.169.13] Traceback (most recent call last):
[Mon Mar 17 20:47:18 2014] [error] [client 58.34.169.13]   File "/home/lanli/jiebademo/jiebademo/adapter.wsgi", line 13, in <module>
[Mon Mar 17 20:47:18 2014] [error] [client 58.34.169.13]     import wsgi # This loads your application
[Mon Mar 17 20:47:18 2014] [error] [client 58.34.169.13]   File "/home/lanli/jiebademo/jiebademo/wsgi.py", line 1, in <module>
[Mon Mar 17 20:47:18 2014] [error] [client 58.34.169.13]     usr/bin/python
[Mon Mar 17 20:47:18 2014] [error] [client 58.34.169.13] NameError: name 'usr' is not defined
[Mon Mar 17 20:47:18 2014] [error] [client 58.34.169.13] mod_wsgi (pid=5217): Target WSGI script '/home/lanli/jiebademo/jiebademo/adapter.wsgi' cannot be loaded as Python module.
[Mon Mar 17 20:47:18 2014] [error] [client 58.34.169.13] mod_wsgi (pid=5217): Exception occurred processing WSGI script '/home/lanli/jiebademo/jiebademo/adapter.wsgi'.
[Mon Mar 17 20:47:18 2014] [error] [client 58.34.169.13] Traceback (most recent call last):
[Mon Mar 17 20:47:18 2014] [error] [client 58.34.169.13]   File "/home/lanli/jiebademo/jiebademo/adapter.wsgi", line 13, in <module>
[Mon Mar 17 20:47:18 2014] [error] [client 58.34.169.13]     import wsgi # This loads your application
[Mon Mar 17 20:47:18 2014] [error] [client 58.34.169.13]   File "/home/lanli/jiebademo/jiebademo/wsgi.py", line 1, in <module>
[Mon Mar 17 20:47:18 2014] [error] [client 58.34.169.13]     usr/bin/python
[Mon Mar 17 20:47:18 2014] [error] [client 58.34.169.13] NameError: name 'usr' is not defined
[Mon Mar 17 20:47:20 2014] [error] [client 58.34.169.13] mod_wsgi (pid=5216): Target WSGI script '/home/lanli/jiebademo/jiebademo/adapter.wsgi' cannot be loaded as Python module.
[Mon Mar 17 20:47:20 2014] [error] [client 58.34.169.13] mod_wsgi (pid=5216): Exception occurred processing WSGI script '/home/lanli/jiebademo/jiebademo/adapter.wsgi'.
[Mon Mar 17 20:47:20 2014] [error] [client 58.34.169.13] Traceback (most recent call last):
[Mon Mar 17 20:47:20 2014] [error] [client 58.34.169.13]   File "/home/lanli/jiebademo/jiebademo/adapter.wsgi", line 13, in <module>
[Mon Mar 17 20:47:20 2014] [error] [client 58.34.169.13]     import wsgi # This loads your application
[Mon Mar 17 20:47:20 2014] [error] [client 58.34.169.13]   File "/home/lanli/jiebademo/jiebademo/wsgi.py", line 1, in <module>
[Mon Mar 17 20:47:20 2014] [error] [client 58.34.169.13]     usr/bin/python
[Mon Mar 17 20:47:20 2014] [error] [client 58.34.169.13] NameError: name 'usr' is not defined
[Mon Mar 17 20:47:20 2014] [error] [client 58.34.169.13] mod_wsgi (pid=5217): Target WSGI script '/home/lanli/jiebademo/jiebademo/adapter.wsgi' cannot be loaded as Python module.
[Mon Mar 17 20:47:20 2014] [error] [client 58.34.169.13] mod_wsgi (pid=5217): Exception occurred processing WSGI script '/home/lanli/jiebademo/jiebademo/adapter.wsgi'.
[Mon Mar 17 20:47:20 2014] [error] [client 58.34.169.13] Traceback (most recent call last):
[Mon Mar 17 20:47:20 2014] [error] [client 58.34.169.13]   File "/home/lanli/jiebademo/jiebademo/adapter.wsgi", line 13, in <module>
[Mon Mar 17 20:47:20 2014] [error] [client 58.34.169.13]     import wsgi # This loads your application
[Mon Mar 17 20:47:20 2014] [error] [client 58.34.169.13]   File "/home/lanli/jiebademo/jiebademo/wsgi.py", line 1, in <module>
[Mon Mar 17 20:47:20 2014] [error] [client 58.34.169.13]     usr/bin/python
[Mon Mar 17 20:47:20 2014] [error] [client 58.34.169.13] NameError: name 'usr' is not defined
[Mon Mar 17 21:23:21 2014] [error] [client 58.34.169.13] mod_wsgi (pid=6884): Target WSGI script '/home/lanli/jiebademo/jiebademo/adapter.wsgi' cannot be loaded as Python module.
[Mon Mar 17 21:23:21 2014] [error] [client 58.34.169.13] mod_wsgi (pid=6884): Exception occurred processing WSGI script '/home/lanli/jiebademo/jiebademo/adapter.wsgi'.
[Mon Mar 17 21:23:21 2014] [error] [client 58.34.169.13] Traceback (most recent call last):
[Mon Mar 17 21:23:21 2014] [error] [client 58.34.169.13]   File "/home/lanli/jiebademo/jiebademo/adapter.wsgi", line 13, in <module>
[Mon Mar 17 21:23:21 2014] [error] [client 58.34.169.13]     import wsgi # This loads your application
[Mon Mar 17 21:23:21 2014] [error] [client 58.34.169.13]   File "/home/lanli/jiebademo/jiebademo/wsgi.py", line 6, in <module>
[Mon Mar 17 21:23:21 2014] [error] [client 58.34.169.13]     path = os.path.dirname(os.path.abspath(__file__))
[Mon Mar 17 21:23:21 2014] [error] [client 58.34.169.13] NameError: name 'os' is not defined
[Mon Mar 17 21:23:21 2014] [error] [client 58.34.169.13] mod_wsgi (pid=6883): Target WSGI script '/home/lanli/jiebademo/jiebademo/adapter.wsgi' cannot be loaded as Python module.
[Mon Mar 17 21:23:21 2014] [error] [client 58.34.169.13] mod_wsgi (pid=6883): Exception occurred processing WSGI script '/home/lanli/jiebademo/jiebademo/adapter.wsgi'.
[Mon Mar 17 21:23:21 2014] [error] [client 58.34.169.13] Traceback (most recent call last):
[Mon Mar 17 21:23:21 2014] [error] [client 58.34.169.13]   File "/home/lanli/jiebademo/jiebademo/adapter.wsgi", line 13, in <module>
[Mon Mar 17 21:23:21 2014] [error] [client 58.34.169.13]     import wsgi # This loads your application
[Mon Mar 17 21:23:21 2014] [error] [client 58.34.169.13]   File "/home/lanli/jiebademo/jiebademo/wsgi.py", line 6, in <module>
[Mon Mar 17 21:23:21 2014] [error] [client 58.34.169.13]     path = os.path.dirname(os.path.abspath(__file__))
[Mon Mar 17 21:23:21 2014] [error] [client 58.34.169.13] NameError: name 'os' is not defined
[Mon Mar 17 21:23:25 2014] [error] [client 58.34.169.13] mod_wsgi (pid=6884): Target WSGI script '/home/lanli/jiebademo/jiebademo/adapter.wsgi' cannot be loaded as Python module.
[Mon Mar 17 21:23:25 2014] [error] [client 58.34.169.13] mod_wsgi (pid=6884): Exception occurred processing WSGI script '/home/lanli/jiebademo/jiebademo/adapter.wsgi'.
[Mon Mar 17 21:23:25 2014] [error] [client 58.34.169.13] Traceback (most recent call last):
[Mon Mar 17 21:23:25 2014] [error] [client 58.34.169.13]   File "/home/lanli/jiebademo/jiebademo/adapter.wsgi", line 13, in <module>
[Mon Mar 17 21:23:25 2014] [error] [client 58.34.169.13]     import wsgi # This loads your application
[Mon Mar 17 21:23:25 2014] [error] [client 58.34.169.13]   File "/home/lanli/jiebademo/jiebademo/wsgi.py", line 6, in <module>
[Mon Mar 17 21:23:25 2014] [error] [client 58.34.169.13]     path = os.path.dirname(os.path.abspath(__file__))
[Mon Mar 17 21:23:25 2014] [error] [client 58.34.169.13] NameError: name 'os' is not defined
[Mon Mar 17 21:23:25 2014] [error] [client 58.34.169.13] mod_wsgi (pid=6883): Target WSGI script '/home/lanli/jiebademo/jiebademo/adapter.wsgi' cannot be loaded as Python module.
[Mon Mar 17 21:23:25 2014] [error] [client 58.34.169.13] mod_wsgi (pid=6883): Exception occurred processing WSGI script '/home/lanli/jiebademo/jiebademo/adapter.wsgi'.
[Mon Mar 17 21:23:25 2014] [error] [client 58.34.169.13] Traceback (most recent call last):
[Mon Mar 17 21:23:25 2014] [error] [client 58.34.169.13]   File "/home/lanli/jiebademo/jiebademo/adapter.wsgi", line 13, in <module>
[Mon Mar 17 21:23:25 2014] [error] [client 58.34.169.13]     import wsgi # This loads your application
[Mon Mar 17 21:23:25 2014] [error] [client 58.34.169.13]   File "/home/lanli/jiebademo/jiebademo/wsgi.py", line 6, in <module>
[Mon Mar 17 21:23:25 2014] [error] [client 58.34.169.13]     path = os.path.dirname(os.path.abspath(__file__))
[Mon Mar 17 21:23:25 2014] [error] [client 58.34.169.13] NameError: name 'os' is not defined
[Mon Mar 17 21:37:26 2014] [error] [client 58.34.169.13] Traceback (most recent call last):, referer: http://42.121.109.6:8088/
[Mon Mar 17 21:37:26 2014] [error] [client 58.34.169.13]   File "/usr/lib/python2.7/dist-packages/bottle.py", line 737, in _handle, referer: http://42.121.109.6:8088/
[Mon Mar 17 21:37:26 2014] [error] [client 58.34.169.13]     return route.call(**args), referer: http://42.121.109.6:8088/
[Mon Mar 17 21:37:26 2014] [error] [client 58.34.169.13]   File "/usr/lib/python2.7/dist-packages/bottle.py", line 1454, in wrapper, referer: http://42.121.109.6:8088/
[Mon Mar 17 21:37:26 2014] [error] [client 58.34.169.13]     rv = callback(*a, **ka), referer: http://42.121.109.6:8088/
[Mon Mar 17 21:37:26 2014] [error] [client 58.34.169.13]   File "/home/lanli/jiebademo/jiebademo/wsgi.py", line 151, in extractFile_action, referer: http://42.121.109.6:8088/
[Mon Mar 17 21:37:26 2014] [error] [client 58.34.169.13]     plt.savefig(imgUrl, bbox_inches='tight'), referer: http://42.121.109.6:8088/
[Mon Mar 17 21:37:26 2014] [error] [client 58.34.169.13]   File "/usr/lib/pymodules/python2.7/matplotlib/pyplot.py", line 471, in savefig, referer: http://42.121.109.6:8088/
[Mon Mar 17 21:37:26 2014] [error] [client 58.34.169.13]     return fig.savefig(*args, **kwargs), referer: http://42.121.109.6:8088/
[Mon Mar 17 21:37:26 2014] [error] [client 58.34.169.13]   File "/usr/lib/pymodules/python2.7/matplotlib/figure.py", line 1185, in savefig, referer: http://42.121.109.6:8088/
[Mon Mar 17 21:37:26 2014] [error] [client 58.34.169.13]     self.canvas.print_figure(*args, **kwargs), referer: http://42.121.109.6:8088/
[Mon Mar 17 21:37:26 2014] [error] [client 58.34.169.13]   File "/usr/lib/pymodules/python2.7/matplotlib/backend_bases.py", line 1983, in print_figure, referer: http://42.121.109.6:8088/
[Mon Mar 17 21:37:26 2014] [error] [client 58.34.169.13]     **kwargs), referer: http://42.121.109.6:8088/
[Mon Mar 17 21:37:26 2014] [error] [client 58.34.169.13]   File "/usr/lib/pymodules/python2.7/matplotlib/backends/backend_agg.py", line 469, in print_png, referer: http://42.121.109.6:8088/
[Mon Mar 17 21:37:26 2014] [error] [client 58.34.169.13]     FigureCanvasAgg.draw(self), referer: http://42.121.109.6:8088/
[Mon Mar 17 21:37:26 2014] [error] [client 58.34.169.13]   File "/usr/lib/pymodules/python2.7/matplotlib/backends/backend_agg.py", line 421, in draw, referer: http://42.121.109.6:8088/
[Mon Mar 17 21:37:26 2014] [error] [client 58.34.169.13]     self.figure.draw(self.renderer), referer: http://42.121.109.6:8088/
[Mon Mar 17 21:37:26 2014] [error] [client 58.34.169.13]   File "/usr/lib/pymodules/python2.7/matplotlib/artist.py", line 55, in draw_wrapper, referer: http://42.121.109.6:8088/
[Mon Mar 17 21:37:26 2014] [error] [client 58.34.169.13]     draw(artist, renderer, *args, **kwargs), referer: http://42.121.109.6:8088/
[Mon Mar 17 21:37:26 2014] [error] [client 58.34.169.13]   File "/usr/lib/pymodules/python2.7/matplotlib/figure.py", line 898, in draw, referer: http://42.121.109.6:8088/
[Mon Mar 17 21:37:26 2014] [error] [client 58.34.169.13]     func(*args), referer: http://42.121.109.6:8088/
[Mon Mar 17 21:37:26 2014] [error] [client 58.34.169.13] RuntimeError: Could not open facefile /Library/Fonts/Songti.ttc; Cannot_Open_Resource, referer: http://42.121.109.6:8088/
[Mon Mar 17 21:37:26 2014] [error] [client 58.34.169.13] , referer: http://42.121.109.6:8088/
[Mon Mar 17 21:40:20 2014] [error] [client 58.34.169.13] Traceback (most recent call last):, referer: http://42.121.109.6:8088/wangyangming.txt
[Mon Mar 17 21:40:20 2014] [error] [client 58.34.169.13]   File "/usr/lib/python2.7/dist-packages/bottle.py", line 737, in _handle, referer: http://42.121.109.6:8088/wangyangming.txt
[Mon Mar 17 21:40:20 2014] [error] [client 58.34.169.13]     return route.call(**args), referer: http://42.121.109.6:8088/wangyangming.txt
[Mon Mar 17 21:40:20 2014] [error] [client 58.34.169.13]   File "/usr/lib/python2.7/dist-packages/bottle.py", line 1454, in wrapper, referer: http://42.121.109.6:8088/wangyangming.txt
[Mon Mar 17 21:40:20 2014] [error] [client 58.34.169.13]     rv = callback(*a, **ka), referer: http://42.121.109.6:8088/wangyangming.txt
[Mon Mar 17 21:40:20 2014] [error] [client 58.34.169.13]   File "/home/lanli/jiebademo/jiebademo/wsgi.py", line 109, in extractFile_action, referer: http://42.121.109.6:8088/wangyangming.txt
[Mon Mar 17 21:40:20 2014] [error] [client 58.34.169.13]     text = open(path + '/files/'+filename, 'rb').read(), referer: http://42.121.109.6:8088/wangyangming.txt
[Mon Mar 17 21:40:20 2014] [error] [client 58.34.169.13] IOError: [Errno 2] No such file or directory: '/home/lanli/jiebademo/jiebademo/files/mozi.txt', referer: http://42.121.109.6:8088/wangyangming.txt
[Mon Mar 17 21:54:22 2014] [error] [client 58.34.169.13] Traceback (most recent call last):, referer: http://42.121.109.6:8088/extract
[Mon Mar 17 21:54:22 2014] [error] [client 58.34.169.13]   File "/usr/lib/python2.7/dist-packages/bottle.py", line 737, in _handle, referer: http://42.121.109.6:8088/extract
[Mon Mar 17 21:54:22 2014] [error] [client 58.34.169.13]     return route.call(**args), referer: http://42.121.109.6:8088/extract
[Mon Mar 17 21:54:22 2014] [error] [client 58.34.169.13]   File "/usr/lib/python2.7/dist-packages/bottle.py", line 1454, in wrapper, referer: http://42.121.109.6:8088/extract
[Mon Mar 17 21:54:22 2014] [error] [client 58.34.169.13]     rv = callback(*a, **ka), referer: http://42.121.109.6:8088/extract
[Mon Mar 17 21:54:22 2014] [error] [client 58.34.169.13]   File "/home/lanli/jiebademo/jiebademo/wsgi.py", line 179, in extractSubmit_action, referer: http://42.121.109.6:8088/extract
[Mon Mar 17 21:54:22 2014] [error] [client 58.34.169.13]     open(path + '/files/' + fn, 'wb').write(text), referer: http://42.121.109.6:8088/extract
[Mon Mar 17 21:54:22 2014] [error] [client 58.34.169.13] IOError: [Errno 13] Permission denied: '/home/lanli/jiebademo/jiebademo/files/\\xe6\\x9b\\xbe\\xe5\\x9b\\xbd\\xe8\\x97\\xa9\\xe5\\xae\\xb6\\xe8\\xae\\xad.txt', referer: http://42.121.109.6:8088/extract
[Mon Mar 17 21:54:29 2014] [error] [client 58.34.169.13] Traceback (most recent call last):, referer: http://42.121.109.6:8088/extract
[Mon Mar 17 21:54:29 2014] [error] [client 58.34.169.13]   File "/usr/lib/python2.7/dist-packages/bottle.py", line 737, in _handle, referer: http://42.121.109.6:8088/extract
[Mon Mar 17 21:54:29 2014] [error] [client 58.34.169.13]     return route.call(**args), referer: http://42.121.109.6:8088/extract
[Mon Mar 17 21:54:29 2014] [error] [client 58.34.169.13]   File "/usr/lib/python2.7/dist-packages/bottle.py", line 1454, in wrapper, referer: http://42.121.109.6:8088/extract
[Mon Mar 17 21:54:29 2014] [error] [client 58.34.169.13]     rv = callback(*a, **ka), referer: http://42.121.109.6:8088/extract
[Mon Mar 17 21:54:29 2014] [error] [client 58.34.169.13]   File "/home/lanli/jiebademo/jiebademo/wsgi.py", line 30, in serve_temp, referer: http://42.121.109.6:8088/extract
[Mon Mar 17 21:54:29 2014] [error] [client 58.34.169.13]     os.remove('./static/temp/' + filename), referer: http://42.121.109.6:8088/extract
[Mon Mar 17 21:54:29 2014] [error] [client 58.34.169.13] OSError: [Errno 2] No such file or directory: './static/temp/test2014-03-17 21:47:59.680358.png', referer: http://42.121.109.6:8088/extract
[Mon Mar 17 22:12:24 2014] [error] [client 58.34.169.13] Traceback (most recent call last):, referer: http://42.121.109.6:8088/extract
[Mon Mar 17 22:12:24 2014] [error] [client 58.34.169.13]   File "/usr/lib/python2.7/dist-packages/bottle.py", line 737, in _handle, referer: http://42.121.109.6:8088/extract
[Mon Mar 17 22:12:24 2014] [error] [client 58.34.169.13]     return route.call(**args), referer: http://42.121.109.6:8088/extract
[Mon Mar 17 22:12:24 2014] [error] [client 58.34.169.13]   File "/usr/lib/python2.7/dist-packages/bottle.py", line 1454, in wrapper, referer: http://42.121.109.6:8088/extract
[Mon Mar 17 22:12:24 2014] [error] [client 58.34.169.13]     rv = callback(*a, **ka), referer: http://42.121.109.6:8088/extract
[Mon Mar 17 22:12:24 2014] [error] [client 58.34.169.13]   File "/home/lanli/jiebademo/jiebademo/wsgi.py", line 180, in extractSubmit_action, referer: http://42.121.109.6:8088/extract
[Mon Mar 17 22:12:24 2014] [error] [client 58.34.169.13]     open(path + '/files/' + fn, 'wb').write(text), referer: http://42.121.109.6:8088/extract
[Mon Mar 17 22:12:24 2014] [error] [client 58.34.169.13] IOError: [Errno 13] Permission denied: '/home/lanli/jiebademo/jiebademo/files/\\xe6\\x9b\\xbe\\xe5\\x9b\\xbd\\xe8\\x97\\xa9\\xe5\\xae\\xb6\\xe8\\xae\\xad.txt', referer: http://42.121.109.6:8088/extract
[Mon Mar 17 22:22:53 2014] [error] [client 58.34.169.13] mod_wsgi (pid=9006): Target WSGI script '/home/lanli/jiebademo/jiebademo/adapter.wsgi' cannot be loaded as Python module.
[Mon Mar 17 22:22:53 2014] [error] [client 58.34.169.13] mod_wsgi (pid=9006): Exception occurred processing WSGI script '/home/lanli/jiebademo/jiebademo/adapter.wsgi'.
[Mon Mar 17 22:22:53 2014] [error] [client 58.34.169.13] Traceback (most recent call last):
[Mon Mar 17 22:22:53 2014] [error] [client 58.34.169.13]   File "/home/lanli/jiebademo/jiebademo/adapter.wsgi", line 13, in <module>
[Mon Mar 17 22:22:53 2014] [error] [client 58.34.169.13]     import wsgi # This loads your application
[Mon Mar 17 22:22:53 2014] [error] [client 58.34.169.13]   File "/home/lanli/jiebademo/jiebademo/wsgi.py", line 173
[Mon Mar 17 22:22:53 2014] [error] [client 58.34.169.13]     charencoding = chardet.detect(text)fileitem.filename
[Mon Mar 17 22:22:53 2014] [error] [client 58.34.169.13]                                               ^
[Mon Mar 17 22:22:53 2014] [error] [client 58.34.169.13] SyntaxError: invalid syntax
[Mon Mar 17 22:22:53 2014] [error] [client 58.34.169.13] mod_wsgi (pid=9005): Target WSGI script '/home/lanli/jiebademo/jiebademo/adapter.wsgi' cannot be loaded as Python module.
[Mon Mar 17 22:22:53 2014] [error] [client 58.34.169.13] mod_wsgi (pid=9005): Exception occurred processing WSGI script '/home/lanli/jiebademo/jiebademo/adapter.wsgi'.
[Mon Mar 17 22:22:53 2014] [error] [client 58.34.169.13] Traceback (most recent call last):
[Mon Mar 17 22:22:53 2014] [error] [client 58.34.169.13]   File "/home/lanli/jiebademo/jiebademo/adapter.wsgi", line 13, in <module>
[Mon Mar 17 22:22:53 2014] [error] [client 58.34.169.13]     import wsgi # This loads your application
[Mon Mar 17 22:22:53 2014] [error] [client 58.34.169.13]   File "/home/lanli/jiebademo/jiebademo/wsgi.py", line 173
[Mon Mar 17 22:22:53 2014] [error] [client 58.34.169.13]     charencoding = chardet.detect(text)fileitem.filename
[Mon Mar 17 22:22:53 2014] [error] [client 58.34.169.13]                                               ^
[Mon Mar 17 22:22:53 2014] [error] [client 58.34.169.13] SyntaxError: invalid syntax
[Mon Mar 17 22:24:08 2014] [error] [client 58.34.169.13] Traceback (most recent call last):, referer: http://42.121.109.6:8088/extract
[Mon Mar 17 22:24:08 2014] [error] [client 58.34.169.13]   File "/usr/lib/python2.7/dist-packages/bottle.py", line 737, in _handle, referer: http://42.121.109.6:8088/extract
[Mon Mar 17 22:24:08 2014] [error] [client 58.34.169.13]     return route.call(**args), referer: http://42.121.109.6:8088/extract
[Mon Mar 17 22:24:08 2014] [error] [client 58.34.169.13]   File "/usr/lib/python2.7/dist-packages/bottle.py", line 1454, in wrapper, referer: http://42.121.109.6:8088/extract
[Mon Mar 17 22:24:08 2014] [error] [client 58.34.169.13]     rv = callback(*a, **ka), referer: http://42.121.109.6:8088/extract
[Mon Mar 17 22:24:08 2014] [error] [client 58.34.169.13]   File "/home/lanli/jiebademo/jiebademo/wsgi.py", line 183, in extractSubmit_action, referer: http://42.121.109.6:8088/extract
[Mon Mar 17 22:24:08 2014] [error] [client 58.34.169.13]     open(path + '/files/' + fn, 'wb').write(text), referer: http://42.121.109.6:8088/extract
[Mon Mar 17 22:24:08 2014] [error] [client 58.34.169.13] IOError: [Errno 13] Permission denied: '/home/lanli/jiebademo/jiebademo/files/\\xe6\\x9b\\xbe\\xe5\\x9b\\xbd\\xe8\\x97\\xa9\\xe5\\xae\\xb6\\xe8\\xae\\xad.txt', referer: http://42.121.109.6:8088/extract
[Mon Mar 17 22:30:13 2014] [error] [client 58.34.169.13] Traceback (most recent call last):, referer: http://42.121.109.6:8088/extract
[Mon Mar 17 22:30:13 2014] [error] [client 58.34.169.13]   File "/usr/lib/python2.7/dist-packages/bottle.py", line 737, in _handle, referer: http://42.121.109.6:8088/extract
[Mon Mar 17 22:30:13 2014] [error] [client 58.34.169.13]     return route.call(**args), referer: http://42.121.109.6:8088/extract
[Mon Mar 17 22:30:13 2014] [error] [client 58.34.169.13]   File "/usr/lib/python2.7/dist-packages/bottle.py", line 1454, in wrapper, referer: http://42.121.109.6:8088/extract
[Mon Mar 17 22:30:13 2014] [error] [client 58.34.169.13]     rv = callback(*a, **ka), referer: http://42.121.109.6:8088/extract
[Mon Mar 17 22:30:13 2014] [error] [client 58.34.169.13]   File "/home/lanli/jiebademo/jiebademo/wsgi.py", line 176, in extractSubmit_action, referer: http://42.121.109.6:8088/extract
[Mon Mar 17 22:30:13 2014] [error] [client 58.34.169.13]     fn = fileitem.filename.encode("utf-8"), referer: http://42.121.109.6:8088/extract
[Mon Mar 17 22:30:13 2014] [error] [client 58.34.169.13] UnicodeDecodeError: 'ascii' codec can't decode byte 0xe6 in position 0: ordinal not in range(128), referer: http://42.121.109.6:8088/extract
[Mon Mar 17 22:37:12 2014] [error] [client 58.34.169.13] Traceback (most recent call last):, referer: http://42.121.109.6:8088/extract
[Mon Mar 17 22:37:12 2014] [error] [client 58.34.169.13]   File "/usr/lib/python2.7/dist-packages/bottle.py", line 737, in _handle, referer: http://42.121.109.6:8088/extract
[Mon Mar 17 22:37:12 2014] [error] [client 58.34.169.13]     return route.call(**args), referer: http://42.121.109.6:8088/extract
[Mon Mar 17 22:37:12 2014] [error] [client 58.34.169.13]   File "/usr/lib/python2.7/dist-packages/bottle.py", line 1454, in wrapper, referer: http://42.121.109.6:8088/extract
[Mon Mar 17 22:37:12 2014] [error] [client 58.34.169.13]     rv = callback(*a, **ka), referer: http://42.121.109.6:8088/extract
[Mon Mar 17 22:37:12 2014] [error] [client 58.34.169.13]   File "/home/lanli/jiebademo/jiebademo/wsgi.py", line 180, in extractSubmit_action, referer: http://42.121.109.6:8088/extract
[Mon Mar 17 22:37:12 2014] [error] [client 58.34.169.13]     open(path + u'/files/' + fn, 'wb').write(text), referer: http://42.121.109.6:8088/extract
[Mon Mar 17 22:37:12 2014] [error] [client 58.34.169.13] UnicodeDecodeError: 'ascii' codec can't decode byte 0xe6 in position 0: ordinal not in range(128), referer: http://42.121.109.6:8088/extract
[Mon Mar 17 22:42:50 2014] [error] [client 58.34.169.13] Traceback (most recent call last):, referer: http://42.121.109.6:8088/extract
[Mon Mar 17 22:42:50 2014] [error] [client 58.34.169.13]   File "/usr/lib/python2.7/dist-packages/bottle.py", line 737, in _handle, referer: http://42.121.109.6:8088/extract
[Mon Mar 17 22:42:50 2014] [error] [client 58.34.169.13]     return route.call(**args), referer: http://42.121.109.6:8088/extract
[Mon Mar 17 22:42:50 2014] [error] [client 58.34.169.13]   File "/usr/lib/python2.7/dist-packages/bottle.py", line 1454, in wrapper, referer: http://42.121.109.6:8088/extract
[Mon Mar 17 22:42:50 2014] [error] [client 58.34.169.13]     rv = callback(*a, **ka), referer: http://42.121.109.6:8088/extract
[Mon Mar 17 22:42:50 2014] [error] [client 58.34.169.13]   File "/home/lanli/jiebademo/jiebademo/wsgi.py", line 31, in serve_temp, referer: http://42.121.109.6:8088/extract
[Mon Mar 17 22:42:50 2014] [error] [client 58.34.169.13]     os.remove(path + '/static/temp/' + filename), referer: http://42.121.109.6:8088/extract
[Mon Mar 17 22:42:50 2014] [error] [client 58.34.169.13] OSError: [Errno 2] No such file or directory: '/home/lanli/jiebademo/jiebademo/static/temp/test2014-03-17 22:42:35.898804.png', referer: http://42.121.109.6:8088/extract
[Mon Mar 17 23:05:35 2014] [error] [client 58.34.169.13] Traceback (most recent call last):, referer: http://42.121.109.6:8088/%E6%9B%BE%E5%9B%BD%E8%97%A9%E5%AE%B6%E8%AE%AD2.txt
[Mon Mar 17 23:05:35 2014] [error] [client 58.34.169.13]   File "/usr/lib/python2.7/dist-packages/bottle.py", line 737, in _handle, referer: http://42.121.109.6:8088/%E6%9B%BE%E5%9B%BD%E8%97%A9%E5%AE%B6%E8%AE%AD2.txt
[Mon Mar 17 23:05:35 2014] [error] [client 58.34.169.13]     return route.call(**args), referer: http://42.121.109.6:8088/%E6%9B%BE%E5%9B%BD%E8%97%A9%E5%AE%B6%E8%AE%AD2.txt
[Mon Mar 17 23:05:35 2014] [error] [client 58.34.169.13]   File "/usr/lib/python2.7/dist-packages/bottle.py", line 1454, in wrapper, referer: http://42.121.109.6:8088/%E6%9B%BE%E5%9B%BD%E8%97%A9%E5%AE%B6%E8%AE%AD2.txt
[Mon Mar 17 23:05:35 2014] [error] [client 58.34.169.13]     rv = callback(*a, **ka), referer: http://42.121.109.6:8088/%E6%9B%BE%E5%9B%BD%E8%97%A9%E5%AE%B6%E8%AE%AD2.txt
[Mon Mar 17 23:05:35 2014] [error] [client 58.34.169.13]   File "/home/lanli/jiebademo/jiebademo/wsgi.py", line 180, in extractSubmit_action, referer: http://42.121.109.6:8088/%E6%9B%BE%E5%9B%BD%E8%97%A9%E5%AE%B6%E8%AE%AD2.txt
[Mon Mar 17 23:05:35 2014] [error] [client 58.34.169.13]     open('files/' + fn, 'wb').write(text), referer: http://42.121.109.6:8088/%E6%9B%BE%E5%9B%BD%E8%97%A9%E5%AE%B6%E8%AE%AD2.txt
[Mon Mar 17 23:05:35 2014] [error] [client 58.34.169.13] IOError: [Errno 13] Permission denied: 'files/\\xe7\\xba\\xaf\\xe7\\xb2\\xb9\\xe7\\x90\\x86\\xe6\\x80\\xa7\\xe6\\x89\\xb9\\xe5\\x88\\xa4+[\\xe5\\xbe\\xb7]\\xe5\\xba\\xb7\\xe5\\xbe\\xb7+\\xe7\\x9d\\x80+\\xe8\\x93\\x9d\\xe5\\x85\\xac\\xe6\\xad\\xa6+\\xe8\\xaf\\x91.txt', referer: http://42.121.109.6:8088/%E6%9B%BE%E5%9B%BD%E8%97%A9%E5%AE%B6%E8%AE%AD2.txt
[Mon Mar 17 23:05:47 2014] [error] [client 58.34.169.13] Traceback (most recent call last):, referer: http://42.121.109.6:8088/%E6%9B%BE%E5%9B%BD%E8%97%A9%E5%AE%B6%E8%AE%AD2.txt
[Mon Mar 17 23:05:47 2014] [error] [client 58.34.169.13]   File "/usr/lib/python2.7/dist-packages/bottle.py", line 737, in _handle, referer: http://42.121.109.6:8088/%E6%9B%BE%E5%9B%BD%E8%97%A9%E5%AE%B6%E8%AE%AD2.txt
[Mon Mar 17 23:05:47 2014] [error] [client 58.34.169.13]     return route.call(**args), referer: http://42.121.109.6:8088/%E6%9B%BE%E5%9B%BD%E8%97%A9%E5%AE%B6%E8%AE%AD2.txt
[Mon Mar 17 23:05:47 2014] [error] [client 58.34.169.13]   File "/usr/lib/python2.7/dist-packages/bottle.py", line 1454, in wrapper, referer: http://42.121.109.6:8088/%E6%9B%BE%E5%9B%BD%E8%97%A9%E5%AE%B6%E8%AE%AD2.txt
[Mon Mar 17 23:05:47 2014] [error] [client 58.34.169.13]     rv = callback(*a, **ka), referer: http://42.121.109.6:8088/%E6%9B%BE%E5%9B%BD%E8%97%A9%E5%AE%B6%E8%AE%AD2.txt
[Mon Mar 17 23:05:47 2014] [error] [client 58.34.169.13]   File "/home/lanli/jiebademo/jiebademo/wsgi.py", line 180, in extractSubmit_action, referer: http://42.121.109.6:8088/%E6%9B%BE%E5%9B%BD%E8%97%A9%E5%AE%B6%E8%AE%AD2.txt
[Mon Mar 17 23:05:47 2014] [error] [client 58.34.169.13]     open('files/' + fn, 'wb').write(text), referer: http://42.121.109.6:8088/%E6%9B%BE%E5%9B%BD%E8%97%A9%E5%AE%B6%E8%AE%AD2.txt
[Mon Mar 17 23:05:47 2014] [error] [client 58.34.169.13] IOError: [Errno 13] Permission denied: 'files/\\xe7\\xba\\xaf\\xe7\\xb2\\xb9\\xe7\\x90\\x86\\xe6\\x80\\xa7\\xe6\\x89\\xb9\\xe5\\x88\\xa4[\\xe5\\xbe\\xb7]\\xe5\\xba\\xb7\\xe5\\xbe\\xb7\\xe7\\x9d\\x80\\xe8\\x93\\x9d\\xe5\\x85\\xac\\xe6\\xad\\xa6\\xe8\\xaf\\x91.txt', referer: http://42.121.109.6:8088/%E6%9B%BE%E5%9B%BD%E8%97%A9%E5%AE%B6%E8%AE%AD2.txt
[Mon Mar 17 23:08:09 2014] [error] [client 58.34.169.13] Traceback (most recent call last):, referer: http://42.121.109.6:8088/extract
[Mon Mar 17 23:08:09 2014] [error] [client 58.34.169.13]   File "/usr/lib/python2.7/dist-packages/bottle.py", line 737, in _handle, referer: http://42.121.109.6:8088/extract
[Mon Mar 17 23:08:09 2014] [error] [client 58.34.169.13]     return route.call(**args), referer: http://42.121.109.6:8088/extract
[Mon Mar 17 23:08:09 2014] [error] [client 58.34.169.13]   File "/usr/lib/python2.7/dist-packages/bottle.py", line 1454, in wrapper, referer: http://42.121.109.6:8088/extract
[Mon Mar 17 23:08:09 2014] [error] [client 58.34.169.13]     rv = callback(*a, **ka), referer: http://42.121.109.6:8088/extract
[Mon Mar 17 23:08:09 2014] [error] [client 58.34.169.13]   File "/home/lanli/jiebademo/jiebademo/wsgi.py", line 31, in serve_temp, referer: http://42.121.109.6:8088/extract
[Mon Mar 17 23:08:09 2014] [error] [client 58.34.169.13]     os.remove(path + '/static/temp/' + filename), referer: http://42.121.109.6:8088/extract
[Mon Mar 17 23:08:09 2014] [error] [client 58.34.169.13] OSError: [Errno 2] No such file or directory: '/home/lanli/jiebademo/jiebademo/static/temp/test2014-03-17 23:07:49.312876.png', referer: http://42.121.109.6:8088/extract
[Mon Mar 17 23:08:44 2014] [error] [client 58.34.169.13] Traceback (most recent call last):, referer: http://42.121.109.6:8088/extract
[Mon Mar 17 23:08:44 2014] [error] [client 58.34.169.13]   File "/usr/lib/python2.7/dist-packages/bottle.py", line 737, in _handle, referer: http://42.121.109.6:8088/extract
[Mon Mar 17 23:08:44 2014] [error] [client 58.34.169.13]     return route.call(**args), referer: http://42.121.109.6:8088/extract
[Mon Mar 17 23:08:44 2014] [error] [client 58.34.169.13]   File "/usr/lib/python2.7/dist-packages/bottle.py", line 1454, in wrapper, referer: http://42.121.109.6:8088/extract
[Mon Mar 17 23:08:44 2014] [error] [client 58.34.169.13]     rv = callback(*a, **ka), referer: http://42.121.109.6:8088/extract
[Mon Mar 17 23:08:44 2014] [error] [client 58.34.169.13]   File "/home/lanli/jiebademo/jiebademo/wsgi.py", line 180, in extractSubmit_action, referer: http://42.121.109.6:8088/extract
[Mon Mar 17 23:08:44 2014] [error] [client 58.34.169.13]     open('files/' + fn, 'wb').write(text), referer: http://42.121.109.6:8088/extract
[Mon Mar 17 23:08:44 2014] [error] [client 58.34.169.13] IOError: [Errno 13] Permission denied: 'files/wangyangming.txt', referer: http://42.121.109.6:8088/extract
[Tue Mar 18 17:07:11 2014] [error] [client 114.91.185.137] Traceback (most recent call last):, referer: http://42.121.109.6:8088/extract
[Tue Mar 18 17:07:11 2014] [error] [client 114.91.185.137]   File "/usr/lib/python2.7/dist-packages/bottle.py", line 737, in _handle, referer: http://42.121.109.6:8088/extract
[Tue Mar 18 17:07:11 2014] [error] [client 114.91.185.137]     return route.call(**args), referer: http://42.121.109.6:8088/extract
[Tue Mar 18 17:07:11 2014] [error] [client 114.91.185.137]   File "/usr/lib/python2.7/dist-packages/bottle.py", line 1454, in wrapper, referer: http://42.121.109.6:8088/extract
[Tue Mar 18 17:07:11 2014] [error] [client 114.91.185.137]     rv = callback(*a, **ka), referer: http://42.121.109.6:8088/extract
[Tue Mar 18 17:07:11 2014] [error] [client 114.91.185.137]   File "/home/lanli/jiebademo/jiebademo/wsgi.py", line 31, in serve_temp, referer: http://42.121.109.6:8088/extract
[Tue Mar 18 17:07:11 2014] [error] [client 114.91.185.137]     os.remove(path + '/static/temp/' + filename), referer: http://42.121.109.6:8088/extract
[Tue Mar 18 17:07:11 2014] [error] [client 114.91.185.137] OSError: [Errno 2] No such file or directory: '/home/lanli/jiebademo/jiebademo/static/temp/test2014-03-18 17:06:54.830754.png', referer: http://42.121.109.6:8088/extract
